Workbook

Sheet Data
A1: Transaction_ID | B1: Date | C1: Customer_ID | D1: Customer_Name | E1: Product_ID | F1: Product_Name | G1: Category | H1: Quantity | I1: Unit_Price | J1: Payment_Method | K1: Region | L1: Customer_Segment | M1: Customer_Since | N1: Total_Amount | O1: Month_End | P1: Month_Label | Q1: Days_Since_Purchase | R1: Tenure_Months_At_Purchase | S1: Customer_Code | T1: Filter_Seq
A2: TRX0155 | B2: 45393 | C2: CUST023 | D2: Paul Baker | E2: P009 | F2: Monitor | G2: Electronics | H2: 3 | I2: 249.99 | J2: Cash | K2: Central | L2: Basic | M2: 44425 | N2: =H2*I2 -> 749.97 | O2: =EOMONTH(B2,0) -> 45412 | P2: =TEXT(B2,"mmm yyyy") -> Apr 2024 | Q2: =TODAY()-B2 -> 932 | R2: =IFERROR(DATEDIF(M2,B2,"m"),0) -> 31 | S2: =UPPER(LEFT(D2,1))&UPPER(MID(D2,FIND(" ",D2)+1,1))&"-"&RIGHT(C2,3) -> PB-023 | T2: =IF(AND(K2=Lists_Filter!$J$4,G2=Lists_Filter!$J$5),COUNTIFS(K$2:K2,Lists_Filter!$J$4,G$2:G2,Lists_Filter!$J$5),"")
A3: TRX0023 | B3: 45396 | C3: CUST013 | D3: Joseph Jackson | E3: P009 | F3: Monitor | G3: Electronics | H3: 3 | I3: 249.99 | J3: Credit Card | K3: Central | L3: Premium | M3: 44575 | N3: =H3*I3 -> 749.97 | O3: =EOMONTH(B3,0) -> 45412 | P3: =TEXT(B3,"mmm yyyy") -> Apr 2024 | Q3: =TODAY()-B3 -> 929 | R3: =IFERROR(DATEDIF(M3,B3,"m"),0) -> 27 | S3: =UPPER(LEFT(D3,1))&UPPER(MID(D3,FIND(" ",D3)+1,1))&"-"&RIGHT(C3,3) -> JJ-013 | T3: =IF(AND(K3=Lists_Filter!$J$4,G3=Lists_Filter!$J$5),COUNTIFS(K$2:K3,Lists_Filter!$J$4,G$2:G3,Lists_Filter!$J$5),"")
A4: TRX0139 | B4: 45399 | C4: CUST021 | D4: Kevin Scott | E4: P005 | F4: Blender | G4: Appliances | H4: 3 | I4: 59.99 | J4: PayPal | K4: South | L4: Standard | M4: 45262 | N4: =H4*I4 -> 179.97 | O4: =EOMONTH(B4,0) -> 45412 | P4: =TEXT(B4,"mmm yyyy") -> Apr 2024 | Q4: =TODAY()-B4 -> 926 | R4: =IFERROR(DATEDIF(M4,B4,"m"),0) -> 4 | S4: =UPPER(LEFT(D4,1))&UPPER(MID(D4,FIND(" ",D4)+1,1))&"-"&RIGHT(C4,3) -> KS-021 | T4: =IF(AND(K4=Lists_Filter!$J$4,G4=Lists_Filter!$J$5),COUNTIFS(K$2:K4,Lists_Filter!$J$4,G$2:G4,Lists_Filter!$J$5),"")
A5: TRX0043 | B5: 45400 | C5: CUST046 | D5: Kathleen Bennett | E5: P005 | F5: Blender | G5: Appliances | H5: 3 | I5: 59.99 | J5: Cash | K5: North | L5: Premium | M5: 45114 | N5: =H5*I5 -> 179.97 | O5: =EOMONTH(B5,0) -> 45412 | P5: =TEXT(B5,"mmm yyyy") -> Apr 2024 | Q5: =TODAY()-B5 -> 925 | R5: =IFERROR(DATEDIF(M5,B5,"m"),0) -> 9 | S5: =UPPER(LEFT(D5,1))&UPPER(MID(D5,FIND(" ",D5)+1,1))&"-"&RIGHT(C5,3) -> KB-046 | T5: =IF(AND(K5=Lists_Filter!$J$4,G5=Lists_Filter!$J$5),COUNTIFS(K$2:K5,Lists_Filter!$J$4,G$2:G5,Lists_Filter!$J$5),"")
A6: TRX0212 | B6: 45400 | C6: CUST003 | D6: Michael Brown | E6: P008 | F6: Bookshelf | G6: Furniture | H6: 5 | I6: 149.99 | J6: Credit Card | K6: North | L6: Premium | M6: 45295 | N6: =H6*I6 -> 749.95 | O6: =EOMONTH(B6,0) -> 45412 | P6: =TEXT(B6,"mmm yyyy") -> Apr 2024 | Q6: =TODAY()-B6 -> 925 | R6: =IFERROR(DATEDIF(M6,B6,"m"),0) -> 3 | S6: =UPPER(LEFT(D6,1))&UPPER(MID(D6,FIND(" ",D6)+1,1))&"-"&RIGHT(C6,3) -> MB-003 | T6: =IF(AND(K6=Lists_Filter!$J$4,G6=Lists_Filter!$J$5),COUNTIFS(K$2:K6,Lists_Filter!$J$4,G$2:G6,Lists_Filter!$J$5),"")
A7: TRX0092 | B7: 45403 | C7: CUST024 | D7: Dorothy Nelson | E7: P005 | F7: Blender | G7: Appliances | H7: 2 | I7: 59.99 | J7: Cash | K7: West | L7: Standard | M7: 44746 | N7: =H7*I7 -> 119.98 | O7: =EOMONTH(B7,0) -> 45412 | P7: =TEXT(B7,"mmm yyyy") -> Apr 2024 | Q7: =TODAY()-B7 -> 922 | R7: =IFERROR(DATEDIF(M7,B7,"m"),0) -> 21 | S7: =UPPER(LEFT(D7,1))&UPPER(MID(D7,FIND(" ",D7)+1,1))&"-"&RIGHT(C7,3) -> DN-024 | T7: =IF(AND(K7=Lists_Filter!$J$4,G7=Lists_Filter!$J$5),COUNTIFS(K$2:K7,Lists_Filter!$J$4,G$2:G7,Lists_Filter!$J$5),"")
A8: TRX0193 | B8: 45403 | C8: CUST024 | D8: Dorothy Nelson | E8: P003 | F8: Headphones | G8: Electronics | H8: 5 | I8: 149.99 | J8: Credit Card | K8: Central | L8: Standard | M8: 44418 | N8: =H8*I8 -> 749.95 | O8: =EOMONTH(B8,0) -> 45412 | P8: =TEXT(B8,"mmm yyyy") -> Apr 2024 | Q8: =TODAY()-B8 -> 922 | R8: =IFERROR(DATEDIF(M8,B8,"m"),0) -> 32 | S8: =UPPER(LEFT(D8,1))&UPPER(MID(D8,FIND(" ",D8)+1,1))&"-"&RIGHT(C8,3) -> DN-024 | T8: =IF(AND(K8=Lists_Filter!$J$4,G8=Lists_Filter!$J$5),COUNTIFS(K$2:K8,Lists_Filter!$J$4,G$2:G8,Lists_Filter!$J$5),"")
A9: TRX0240 | B9: 45403 | C9: CUST017 | D9: Charles Allen | E9: P005 | F9: Blender | G9: Appliances | H9: 3 | I9: 59.99 | J9: Debit Card | K9: South | L9: Basic | M9: 45007 | N9: =H9*I9 -> 179.97 | O9: =EOMONTH(B9,0) -> 45412 | P9: =TEXT(B9,"mmm yyyy") -> Apr 2024 | Q9: =TODAY()-B9 -> 922 | R9: =IFERROR(DATEDIF(M9,B9,"m"),0) -> 12 | S9: =UPPER(LEFT(D9,1))&UPPER(MID(D9,FIND(" ",D9)+1,1))&"-"&RIGHT(C9,3) -> CA-017 | T9: =IF(AND(K9=Lists_Filter!$J$4,G9=Lists_Filter!$J$5),COUNTIFS(K$2:K9,Lists_Filter!$J$4,G$2:G9,Lists_Filter!$J$5),"")
A10: TRX0135 | B10: 45405 | C10: CUST009 | D10: Robert Thomas | E10: P001 | F10: Laptop | G10: Electronics | H10: 3 | I10: 899.99 | J10: PayPal | K10: East | L10: Standard | M10: 45299 | N10: =H10*I10 -> 2699.97 | O10: =EOMONTH(B10,0) -> 45412 | P10: =TEXT(B10,"mmm yyyy") -> Apr 2024 | Q10: =TODAY()-B10 -> 920 | R10: =IFERROR(DATEDIF(M10,B10,"m"),0) -> 3 | S10: =UPPER(LEFT(D10,1))&UPPER(MID(D10,FIND(" ",D10)+1,1))&"-"&RIGHT(C10,3) -> RT-009 | T10: =IF(AND(K10=Lists_Filter!$J$4,G10=Lists_Filter!$J$5),COUNTIFS(K$2:K10,Lists_Filter!$J$4,G$2:G10,Lists_Filter!$J$5),"")
A11: TRX0138 | B11: 45408 | C11: CUST022 | D11: Susan Green | E11: P008 | F11: Bookshelf | G11: Furniture | H11: 1 | I11: 149.99 | J11: Credit Card | K11: West | L11: Standard | M11: 45103 | N11: =H11*I11 -> 149.99 | O11: =EOMONTH(B11,0) -> 45412 | P11: =TEXT(B11,"mmm yyyy") -> Apr 2024 | Q11: =TODAY()-B11 -> 917 | R11: =IFERROR(DATEDIF(M11,B11,"m"),0) -> 10 | S11: =UPPER(LEFT(D11,1))&UPPER(MID(D11,FIND(" ",D11)+1,1))&"-"&RIGHT(C11,3) -> SG-022 | T11: =IF(AND(K11=Lists_Filter!$J$4,G11=Lists_Filter!$J$5),COUNTIFS(K$2:K11,Lists_Filter!$J$4,G$2:G11,Lists_Filter!$J$5),"")
A12: TRX0185 | B12: 45408 | C12: CUST026 | D12: Karen Hill | E12: P005 | F12: Blender | G12: Appliances | H12: 3 | I12: 59.99 | J12: Cash | K12: West | L12: Premium | M12: 45207 | N12: =H12*I12 -> 179.97 | O12: =EOMONTH(B12,0) -> 45412 | P12: =TEXT(B12,"mmm yyyy") -> Apr 2024 | Q12: =TODAY()-B12 -> 917 | R12: =IFERROR(DATEDIF(M12,B12,"m"),0) -> 6 | S12: =UPPER(LEFT(D12,1))&UPPER(MID(D12,FIND(" ",D12)+1,1))&"-"&RIGHT(C12,3) -> KH-026 | T12: =IF(AND(K12=Lists_Filter!$J$4,G12=Lists_Filter!$J$5),COUNTIFS(K$2:K12,Lists_Filter!$J$4,G$2:G12,Lists_Filter!$J$5),"")
A13: TRX0209 | B13: 45408 | C13: CUST046 | D13: Kathleen Bennett | E13: P008 | F13: Bookshelf | G13: Furniture | H13: 5 | I13: 149.99 | J13: Debit Card | K13: North | L13: Basic | M13: 44830 | N13: =H13*I13 -> 749.95 | O13: =EOMONTH(B13,0) -> 45412 | P13: =TEXT(B13,"mmm yyyy") -> Apr 2024 | Q13: =TODAY()-B13 -> 917 | R13: =IFERROR(DATEDIF(M13,B13,"m"),0) -> 19 | S13: =UPPER(LEFT(D13,1))&UPPER(MID(D13,FIND(" ",D13)+1,1))&"-"&RIGHT(C13,3) -> KB-046 | T13: =IF(AND(K13=Lists_Filter!$J$4,G13=Lists_Filter!$J$5),COUNTIFS(K$2:K13,Lists_Filter!$J$4,G$2:G13,Lists_Filter!$J$5),"")
... A251: TRX0120 | B251: 45758 | C251: CUST045 | D251: Douglas Watson | E251: P002 | F251: Smartphone | G251: Electronics | H251: 3 | I251: 699.99 | J251: PayPal | K251: North | L251: Basic | M251: 44909 | N251: =H251*I251 -> 2099.97 | O251: =EOMONTH(B251,0) -> 45777 | P251: =TEXT(B251,"mmm yyyy") -> Apr 2025 | Q251: =TODAY()-B251 -> 567 | R251: =IFERROR(DATEDIF(M251,B251,"m"),0) -> 27 | S251: =UPPER(LEFT(D251,1))&UPPER(MID(D251,FIND(" ",D251)+1,1))&"-"&RIGHT(C251,3) -> DW-045 | T251: =IF(AND(K251=Lists_Filter!$J$4,G251=Lists_Filter!$J$5),COUNTIFS(K$2:K251,Lists_Filter!$J$4,G$2:G251,Lists_Filter!$J$5),"") -> 36

Sheet Customers
A1: Customer Analysis - GroupBy with formulas
A2: One row per customer. Every number is SUMIF / COUNTIF over the Data sheet.
A3: High-value threshold (percentile of revenue) | D3: 0.8 | F3: Threshold revenue: | G3: =PERCENTILE(F6:F55,D3) -> 6557.8
A5: Customer_ID | B5: Customer_Name | C5: Code | D5: Orders | E5: Units | F5: Revenue | G5: Avg Order Value | H5: Share of Revenue | I5: Rank | J5: Tier | K5: Last Purchase | L5: Days Since Last | M5: Electronics? | N5: Furniture? | O5: Appliances? | P5: Segments Seen | R5: Top 10 | S5: Customer | T5: Revenue | U5: Orders
A6: CUST001 | B6: =INDEX(Data!$D$2:$D$251,MATCH(A6,Data!$C$2:$C$251,0)) -> John Smith | C6: =INDEX(Data!$S$2:$S$251,MATCH(A6,Data!$C$2:$C$251,0)) -> JS-001 | D6: =COUNTIF(Data!$C$2:$C$251,A6) -> 1 | E6: =SUMIF(Data!$C$2:$C$251,A6,Data!$H$2:$H$251) -> 4 | F6: =SUMIF(Data!$C$2:$C$251,A6,Data!$N$2:$N$251) -> 599.96 | G6: =IF(D6=0,0,F6/D6) -> 599.96 | H6: =F6/SUM($F$6:$F$55) -> 0.0026177125 | I6: =RANK(F6,$F$6:$F$55)+COUNTIF($F$6:F6,F6)-1 -> 47 | J6: =IF(F6>=$G$3,"High-Value","Regular") -> Regular | K6: =SUMPRODUCT(MAX((Data!$C$2:$C$251=A6)*Data!$B$2:$B$251)) -> 45740 | L6: =TODAY()-K6 -> 585 | M6: =IF(COUNTIFS(Data!$C$2:$C$251,$A6,Data!$G$2:$G$251,"Electronics")>0,"Yes","No") -> No | N6: =IF(COUNTIFS(Data!$C$2:$C$251,$A6,Data!$G$2:$G$251,"Furniture")>0,"Yes","No") -> Yes | O6: =IF(COUNTIFS(Data!$C$2:$C$251,$A6,Data!$G$2:$G$251,"Appliances")>0,"Yes","No") -> No | P6: =(COUNTIFS(Data!$C$2:$C$251,A6,Data!$L$2:$L$251,"Basic")>0)+(COUNTIFS(Data!$C$2:$C$251,A6,Data!$L$2:$L$251,"Standard")>0)+(COUNTIFS(Data!$C$2:$C$251,A6,Data!$L$2:$L$251,"Premium")>0) -> 1 | R6: 1 | S6: =INDEX($B$6:$B$55,MATCH(R6,$I$6:$I$55,0)) -> Mark Carter | T6: =INDEX($F$6:$F$55,MATCH(R6,$I$6:$I$55,0)) -> 15659.65 | U6: =INDEX($D$6:$D$55,MATCH(R6,$I$6:$I$55,0)) -> 12
A7: CUST002 | B7: =INDEX(Data!$D$2:$D$251,MATCH(A7,Data!$C$2:$C$251,0)) -> Emma Wilson | C7: =INDEX(Data!$S$2:$S$251,MATCH(A7,Data!$C$2:$C$251,0)) -> EW-002 | D7: =COUNTIF(Data!$C$2:$C$251,A7) -> 5 | E7: =SUMIF(Data!$C$2:$C$251,A7,Data!$H$2:$H$251) -> 12 | F7: =SUMIF(Data!$C$2:$C$251,A7,Data!$N$2:$N$251) -> 1229.88 | G7: =IF(D7=0,0,F7/D7) -> 245.976 | H7: =F7/SUM($F$6:$F$55) -> 0.0053661449 | I7: =RANK(F7,$F$6:$F$55)+COUNTIF($F$6:F7,F7)-1 -> 44 | J7: =IF(F7>=$G$3,"High-Value","Regular") -> Regular | K7: =SUMPRODUCT(MAX((Data!$C$2:$C$251=A7)*Data!$B$2:$B$251)) -> 45737 | L7: =TODAY()-K7 -> 588 | M7: =IF(COUNTIFS(Data!$C$2:$C$251,$A7,Data!$G$2:$G$251,"Electronics")>0,"Yes","No") -> Yes | N7: =IF(COUNTIFS(Data!$C$2:$C$251,$A7,Data!$G$2:$G$251,"Furniture")>0,"Yes","No") -> Yes | O7: =IF(COUNTIFS(Data!$C$2:$C$251,$A7,Data!$G$2:$G$251,"Appliances")>0,"Yes","No") -> Yes | P7: =(COUNTIFS(Data!$C$2:$C$251,A7,Data!$L$2:$L$251,"Basic")>0)+(COUNTIFS(Data!$C$2:$C$251,A7,Data!$L$2:$L$251,"Standard")>0)+(COUNTIFS(Data!$C$2:$C$251,A7,Data!$L$2:$L$251,"Premium")>0) -> 3 | R7: 2 | S7: =INDEX($B$6:$B$55,MATCH(R7,$I$6:$I$55,0)) -> Edward Mitchell | T7: =INDEX($F$6:$F$55,MATCH(R7,$I$6:$I$55,0)) -> 11919.77 | U7: =INDEX($D$6:$D$55,MATCH(R7,$I$6:$I$55,0)) -> 6
A8: CUST003 | B8: =INDEX(Data!$D$2:$D$251,MATCH(A8,Data!$C$2:$C$251,0)) -> Michael Brown | C8: =INDEX(Data!$S$2:$S$251,MATCH(A8,Data!$C$2:$C$251,0)) -> MB-003 | D8: =COUNTIF(Data!$C$2:$C$251,A8) -> 9 | E8: =SUMIF(Data!$C$2:$C$251,A8,Data!$H$2:$H$251) -> 26 | F8: =SUMIF(Data!$C$2:$C$251,A8,Data!$N$2:$N$251) -> 6169.74 | G8: =IF(D8=0,0,F8/D8) -> 685.52667 | H8: =F8/SUM($F$6:$F$55) -> 0.026919471 | I8: =RANK(F8,$F$6:$F$55)+COUNTIF($F$6:F8,F8)-1 -> 14 | J8: =IF(F8>=$G$3,"High-Value","Regular") -> Regular | K8: =SUMPRODUCT(MAX((Data!$C$2:$C$251=A8)*Data!$B$2:$B$251)) -> 45707 | L8: =TODAY()-K8 -> 618 | M8: =IF(COUNTIFS(Data!$C$2:$C$251,$A8,Data!$G$2:$G$251,"Electronics")>0,"Yes","No") -> Yes | N8: =IF(COUNTIFS(Data!$C$2:$C$251,$A8,Data!$G$2:$G$251,"Furniture")>0,"Yes","No") -> Yes | O8: =IF(COUNTIFS(Data!$C$2:$C$251,$A8,Data!$G$2:$G$251,"Appliances")>0,"Yes","No") -> No | P8: =(COUNTIFS(Data!$C$2:$C$251,A8,Data!$L$2:$L$251,"Basic")>0)+(COUNTIFS(Data!$C$2:$C$251,A8,Data!$L$2:$L$251,"Standard")>0)+(COUNTIFS(Data!$C$2:$C$251,A8,Data!$L$2:$L$251,"Premium")>0) -> 3 | R8: 3 | S8: =INDEX($B$6:$B$55,MATCH(R8,$I$6:$I$55,0)) -> Barbara Young | T8: =INDEX($F$6:$F$55,MATCH(R8,$I$6:$I$55,0)) -> 10649.8 | U8: =INDEX($D$6:$D$55,MATCH(R8,$I$6:$I$55,0)) -> 5
A9: CUST004 | B9: =INDEX(Data!$D$2:$D$251,MATCH(A9,Data!$C$2:$C$251,0)) -> Sarah Davis | C9: =INDEX(Data!$S$2:$S$251,MATCH(A9,Data!$C$2:$C$251,0)) -> SD-004 | D9: =COUNTIF(Data!$C$2:$C$251,A9) -> 5 | E9: =SUMIF(Data!$C$2:$C$251,A9,Data!$H$2:$H$251) -> 19 | F9: =SUMIF(Data!$C$2:$C$251,A9,Data!$N$2:$N$251) -> 5499.81 | G9: =IF(D9=0,0,F9/D9) -> 1099.962 | H9: =F9/SUM($F$6:$F$55) -> 0.023996469 | I9: =RANK(F9,$F$6:$F$55)+COUNTIF($F$6:F9,F9)-1 -> 19 | J9: =IF(F9>=$G$3,"High-Value","Regular") -> Regular | K9: =SUMPRODUCT(MAX((Data!$C$2:$C$251=A9)*Data!$B$2:$B$251)) -> 45619 | L9: =TODAY()-K9 -> 706 | M9: =IF(COUNTIFS(Data!$C$2:$C$251,$A9,Data!$G$2:$G$251,"Electronics")>0,"Yes","No") -> Yes | N9: =IF(COUNTIFS(Data!$C$2:$C$251,$A9,Data!$G$2:$G$251,"Furniture")>0,"Yes","No") -> Yes | O9: =IF(COUNTIFS(Data!$C$2:$C$251,$A9,Data!$G$2:$G$251,"Appliances")>0,"Yes","No") -> No | P9: =(COUNTIFS(Data!$C$2:$C$251,A9,Data!$L$2:$L$251,"Basic")>0)+(COUNTIFS(Data!$C$2:$C$251,A9,Data!$L$2:$L$251,"Standard")>0)+(COUNTIFS(Data!$C$2:$C$251,A9,Data!$L$2:$L$251,"Premium")>0) -> 2 | R9: 4 | S9: =INDEX($B$6:$B$55,MATCH(R9,$I$6:$I$55,0)) -> Patricia Moore | T9: =INDEX($F$6:$F$55,MATCH(R9,$I$6:$I$55,0)) -> 9799.73 | U9: =INDEX($D$6:$D$55,MATCH(R9,$I$6:$I$55,0)) -> 8
A10: CUST005 | B10: =INDEX(Data!$D$2:$D$251,MATCH(A10,Data!$C$2:$C$251,0)) -> James Johnson | C10: =INDEX(Data!$S$2:$S$251,MATCH(A10,Data!$C$2:$C$251,0)) -> JJ-005 | D10: =COUNTIF(Data!$C$2:$C$251,A10) -> 1 | E10: =SUMIF(Data!$C$2:$C$251,A10,Data!$H$2:$H$251) -> 3 | F10: =SUMIF(Data!$C$2:$C$251,A10,Data!$N$2:$N$251) -> 179.97 | G10: =IF(D10=0,0,F10/D10) -> 179.97 | H10: =F10/SUM($F$6:$F$55) -> 0.00078523522 | I10: =RANK(F10,$F$6:$F$55)+COUNTIF($F$6:F10,F10)-1 -> 50 | J10: =IF(F10>=$G$3,"High-Value","Regular") -> Regular | K10: =SUMPRODUCT(MAX((Data!$C$2:$C$251=A10)*Data!$B$2:$B$251)) -> 45635 | L10: =TODAY()-K10 -> 690 | M10: =IF(COUNTIFS(Data!$C$2:$C$251,$A10,Data!$G$2:$G$251,"Electronics")>0,"Yes","No") -> No | N10: =IF(COUNTIFS(Data!$C$2:$C$251,$A10,Data!$G$2:$G$251,"Furniture")>0,"Yes","No") -> No | O10: =IF(COUNTIFS(Data!$C$2:$C$251,$A10,Data!$G$2:$G$251,"Appliances")>0,"Yes","No") -> Yes | P10: =(COUNTIFS(Data!$C$2:$C$251,A10,Data!$L$2:$L$251,"Basic")>0)+(COUNTIFS(Data!$C$2:$C$251,A10,Data!$L$2:$L$251,"Standard")>0)+(COUNTIFS(Data!$C$2:$C$251,A10,Data!$L$2:$L$251,"Premium")>0) -> 1 | R10: 5 | S10: =INDEX($B$6:$B$55,MATCH(R10,$I$6:$I$55,0)) -> Paul Baker | T10: =INDEX($F$6:$F$55,MATCH(R10,$I$6:$I$55,0)) -> 8309.74 | U10: =INDEX($D$6:$D$55,MATCH(R10,$I$6:$I$55,0)) -> 8
A11: CUST006 | B11: =INDEX(Data!$D$2:$D$251,MATCH(A11,Data!$C$2:$C$251,0)) -> Lisa Anderson | C11: =INDEX(Data!$S$2:$S$251,MATCH(A11,Data!$C$2:$C$251,0)) -> LA-006 | D11: =COUNTIF(Data!$C$2:$C$251,A11) -> 5 | E11: =SUMIF(Data!$C$2:$C$251,A11,Data!$H$2:$H$251) -> 20 | F11: =SUMIF(Data!$C$2:$C$251,A11,Data!$N$2:$N$251) -> 2039.8 | G11: =IF(D11=0,0,F11/D11) -> 407.96 | H11: =F11/SUM($F$6:$F$55) -> 0.0088999434 | I11: =RANK(F11,$F$6:$F$55)+COUNTIF($F$6:F11,F11)-1 -> 36 | J11: =IF(F11>=$G$3,"High-Value","Regular") -> Regular | K11: =SUMPRODUCT(MAX((Data!$C$2:$C$251=A11)*Data!$B$2:$B$251)) -> 45676 | L11: =TODAY()-K11 -> 649 | M11: =IF(COUNTIFS(Data!$C$2:$C$251,$A11,Data!$G$2:$G$251,"Electronics")>0,"Yes","No") -> Yes | N11: =IF(COUNTIFS(Data!$C$2:$C$251,$A11,Data!$G$2:$G$251,"Furniture")>0,"Yes","No") -> Yes | O11: =IF(COUNTIFS(Data!$C$2:$C$251,$A11,Data!$G$2:$G$251,"Appliances")>0,"Yes","No") -> Yes | P11: =(COUNTIFS(Data!$C$2:$C$251,A11,Data!$L$2:$L$251,"Basic")>0)+(COUNTIFS(Data!$C$2:$C$251,A11,Data!$L$2:$L$251,"Standard")>0)+(COUNTIFS(Data!$C$2:$C$251,A11,Data!$L$2:$L$251,"Premium")>0) -> 2 | R11: 6 | S11: =INDEX($B$6:$B$55,MATCH(R11,$I$6:$I$55,0)) -> Dorothy Nelson | T11: =INDEX($F$6:$F$55,MATCH(R11,$I$6:$I$55,0)) -> 8269.79 | U11: =INDEX($D$6:$D$55,MATCH(R11,$I$6:$I$55,0)) -> 6
A12: CUST007 | B12: =INDEX(Data!$D$2:$D$251,MATCH(A12,Data!$C$2:$C$251,0)) -> David Martinez | C12: =INDEX(Data!$S$2:$S$251,MATCH(A12,Data!$C$2:$C$251,0)) -> DM-007 | D12: =COUNTIF(Data!$C$2:$C$251,A12) -> 6 | E12: =SUMIF(Data!$C$2:$C$251,A12,Data!$H$2:$H$251) -> 16 | F12: =SUMIF(Data!$C$2:$C$251,A12,Data!$N$2:$N$251) -> 1809.84 | G12: =IF(D12=0,0,F12/D12) -> 301.64 | H12: =F12/SUM($F$6:$F$55) -> 0.0078965945 | I12: =RANK(F12,$F$6:$F$55)+COUNTIF($F$6:F12,F12)-1 -> 39 | J12: =IF(F12>=$G$3,"High-Value","Regular") -> Regular | K12: =SUMPRODUCT(MAX((Data!$C$2:$C$251=A12)*Data!$B$2:$B$251)) -> 45648 | L12: =TODAY()-K12 -> 677 | M12: =IF(COUNTIFS(Data!$C$2:$C$251,$A12,Data!$G$2:$G$251,"Electronics")>0,"Yes","No") -> Yes | N12: =IF(COUNTIFS(Data!$C$2:$C$251,$A12,Data!$G$2:$G$251,"Furniture")>0,"Yes","No") -> Yes | O12: =IF(COUNTIFS(Data!$C$2:$C$251,$A12,Data!$G$2:$G$251,"Appliances")>0,"Yes","No") -> Yes | P12: =(COUNTIFS(Data!$C$2:$C$251,A12,Data!$L$2:$L$251,"Basic")>0)+(COUNTIFS(Data!$C$2:$C$251,A12,Data!$L$2:$L$251,"Standard")>0)+(COUNTIFS(Data!$C$2:$C$251,A12,Data!$L$2:$L$251,"Premium")>0) -> 3 | R12: 7 | S12: =INDEX($B$6:$B$55,MATCH(R12,$I$6:$I$55,0)) -> Karen Hill | T12: =INDEX($F$6:$F$55,MATCH(R12,$I$6:$I$55,0)) -> 8009.77 | U12: =INDEX($D$6:$D$55,MATCH(R12,$I$6:$I$55,0)) -> 8
A13: CUST008 | B13: =INDEX(Data!$D$2:$D$251,MATCH(A13,Data!$C$2:$C$251,0)) -> Jennifer Taylor | C13: =INDEX(Data!$S$2:$S$251,MATCH(A13,Data!$C$2:$C$251,0)) -> JT-008 | D13: =COUNTIF(Data!$C$2:$C$251,A13) -> 4 | E13: =SUMIF(Data!$C$2:$C$251,A13,Data!$H$2:$H$251) -> 15 | F13: =SUMIF(Data!$C$2:$C$251,A13,Data!$N$2:$N$251) -> 4739.85 | G13: =IF(D13=0,0,F13/D13) -> 1184.9625 | H13: =F13/SUM($F$6:$F$55) -> 0.020680653 | I13: =RANK(F13,$F$6:$F$55)+COUNTIF($F$6:F13,F13)-1 -> 24 | J13: =IF(F13>=$G$3,"High-Value","Regular") -> Regular | K13: =SUMPRODUCT(MAX((Data!$C$2:$C$251=A13)*Data!$B$2:$B$251)) -> 45635 | L13: =TODAY()-K13 -> 690 | M13: =IF(COUNTIFS(Data!$C$2:$C$251,$A13,Data!$G$2:$G$251,"Electronics")>0,"Yes","No") -> Yes | N13: =IF(COUNTIFS(Data!$C$2:$C$251,$A13,Data!$G$2:$G$251,"Furniture")>0,"Yes","No") -> Yes | O13: =IF(COUNTIFS(Data!$C$2:$C$251,$A13,Data!$G$2:$G$251,"Appliances")>0,"Yes","No") -> Yes | P13: =(COUNTIFS(Data!$C$2:$C$251,A13,Data!$L$2:$L$251,"Basic")>0)+(COUNTIFS(Data!$C$2:$C$251,A13,Data!$L$2:$L$251,"Standard")>0)+(COUNTIFS(Data!$C$2:$C$251,A13,Data!$L$2:$L$251,"Premium")>0) -> 2 | R13: 8 | S13: =INDEX($B$6:$B$55,MATCH(R13,$I$6:$I$55,0)) -> Daniel King | T13: =INDEX($F$6:$F$55,MATCH(R13,$I$6:$I$55,0)) -> 7309.8 | U13: =INDEX($D$6:$D$55,MATCH(R13,$I$6:$I$55,0)) -> 7
A14: CUST009 | B14: =INDEX(Data!$D$2:$D$251,MATCH(A14,Data!$C$2:$C$251,0)) -> Robert Thomas | C14: =INDEX(Data!$S$2:$S$251,MATCH(A14,Data!$C$2:$C$251,0)) -> RT-009 | D14: =COUNTIF(Data!$C$2:$C$251,A14) -> 5 | E14: =SUMIF(Data!$C$2:$C$251,A14,Data!$H$2:$H$251) -> 10 | F14: =SUMIF(Data!$C$2:$C$251,A14,Data!$N$2:$N$251) -> 3509.9 | G14: =IF(D14=0,0,F14/D14) -> 701.98 | H14: =F14/SUM($F$6:$F$55) -> 0.015314203 | I14: =RANK(F14,$F$6:$F$55)+COUNTIF($F$6:F14,F14)-1 -> 32 | J14: =IF(F14>=$G$3,"High-Value","Regular") -> Regular | K14: =SUMPRODUCT(MAX((Data!$C$2:$C$251=A14)*Data!$B$2:$B$251)) -> 45756 | L14: =TODAY()-K14 -> 569 | M14: =IF(COUNTIFS(Data!$C$2:$C$251,$A14,Data!$G$2:$G$251,"Electronics")>0,"Yes","No") -> Yes | N14: =IF(COUNTIFS(Data!$C$2:$C$251,$A14,Data!$G$2:$G$251,"Furniture")>0,"Yes","No") -> Yes | O14: =IF(COUNTIFS(Data!$C$2:$C$251,$A14,Data!$G$2:$G$251,"Appliances")>0,"Yes","No") -> No | P14: =(COUNTIFS(Data!$C$2:$C$251,A14,Data!$L$2:$L$251,"Basic")>0)+(COUNTIFS(Data!$C$2:$C$251,A14,Data!$L$2:$L$251,"Standard")>0)+(COUNTIFS(Data!$C$2:$C$251,A14,Data!$L$2:$L$251,"Premium")>0) -> 3 | R14: 9 | S14: =INDEX($B$6:$B$55,MATCH(R14,$I$6:$I$55,0)) -> Lawrence Reed | T14: =INDEX($F$6:$F$55,MATCH(R14,$I$6:$I$55,0)) -> 6989.77 | U14: =INDEX($D$6:$D$55,MATCH(R14,$I$6:$I$55,0)) -> 8
A15: CUST010 | B15: =INDEX(Data!$D$2:$D$251,MATCH(A15,Data!$C$2:$C$251,0)) -> Maria Garcia | C15: =INDEX(Data!$S$2:$S$251,MATCH(A15,Data!$C$2:$C$251,0)) -> MG-010 | D15: =COUNTIF(Data!$C$2:$C$251,A15) -> 4 | E15: =SUMIF(Data!$C$2:$C$251,A15,Data!$H$2:$H$251) -> 7 | F15: =SUMIF(Data!$C$2:$C$251,A15,Data!$N$2:$N$251) -> 1909.93 | G15: =IF(D15=0,0,F15/D15) -> 477.4825 | H15: =F15/SUM($F$6:$F$55) -> 0.0083333017 | I15: =RANK(F15,$F$6:$F$55)+COUNTIF($F$6:F15,F15)-1 -> 38 | J15: =IF(F15>=$G$3,"High-Value","Regular") -> Regular | K15: =SUMPRODUCT(MAX((Data!$C$2:$C$251=A15)*Data!$B$2:$B$251)) -> 45604 | L15: =TODAY()-K15 -> 721 | M15: =IF(COUNTIFS(Data!$C$2:$C$251,$A15,Data!$G$2:$G$251,"Electronics")>0,"Yes","No") -> Yes | N15: =IF(COUNTIFS(Data!$C$2:$C$251,$A15,Data!$G$2:$G$251,"Furniture")>0,"Yes","No") -> Yes | O15: =IF(COUNTIFS(Data!$C$2:$C$251,$A15,Data!$G$2:$G$251,"Appliances")>0,"Yes","No") -> Yes | P15: =(COUNTIFS(Data!$C$2:$C$251,A15,Data!$L$2:$L$251,"Basic")>0)+(COUNTIFS(Data!$C$2:$C$251,A15,Data!$L$2:$L$251,"Standard")>0)+(COUNTIFS(Data!$C$2:$C$251,A15,Data!$L$2:$L$251,"Premium")>0) -> 3 | R15: 10 | S15: =INDEX($B$6:$B$55,MATCH(R15,$I$6:$I$55,0)) -> Joseph Jackson | T15: =INDEX($F$6:$F$55,MATCH(R15,$I$6:$I$55,0)) -> 6949.84 | U15: =INDEX($D$6:$D$55,MATCH(R15,$I$6:$I$55,0)) -> 5
A16: CUST011 | B16: =INDEX(Data!$D$2:$D$251,MATCH(A16,Data!$C$2:$C$251,0)) -> William White | C16: =INDEX(Data!$S$2:$S$251,MATCH(A16,Data!$C$2:$C$251,0)) -> WW-011 | D16: =COUNTIF(Data!$C$2:$C$251,A16) -> 3 | E16: =SUMIF(Data!$C$2:$C$251,A16,Data!$H$2:$H$251) -> 9 | F16: =SUMIF(Data!$C$2:$C$251,A16,Data!$N$2:$N$251) -> 4749.91 | G16: =IF(D16=0,0,F16/D16) -> 1583.3033 | H16: =F16/SUM($F$6:$F$55) -> 0.020724546 | I16: =RANK(F16,$F$6:$F$55)+COUNTIF($F$6:F16,F16)-1 -> 23 | J16: =IF(F16>=$G$3,"High-Value","Regular") -> Regular | K16: =SUMPRODUCT(MAX((Data!$C$2:$C$251=A16)*Data!$B$2:$B$251)) -> 45686 | L16: =TODAY()-K16 -> 639 | M16: =IF(COUNTIFS(Data!$C$2:$C$251,$A16,Data!$G$2:$G$251,"Electronics")>0,"Yes","No") -> Yes | N16: =IF(COUNTIFS(Data!$C$2:$C$251,$A16,Data!$G$2:$G$251,"Furniture")>0,"Yes","No") -> No | O16: =IF(COUNTIFS(Data!$C$2:$C$251,$A16,Data!$G$2:$G$251,"Appliances")>0,"Yes","No") -> No | P16: =(COUNTIFS(Data!$C$2:$C$251,A16,Data!$L$2:$L$251,"Basic")>0)+(COUNTIFS(Data!$C$2:$C$251,A16,Data!$L$2:$L$251,"Standard")>0)+(COUNTIFS(Data!$C$2:$C$251,A16,Data!$L$2:$L$251,"Premium")>0) -> 3
A17: CUST012 | B17: =INDEX(Data!$D$2:$D$251,MATCH(A17,Data!$C$2:$C$251,0)) -> Patricia Moore | C17: =INDEX(Data!$S$2:$S$251,MATCH(A17,Data!$C$2:$C$251,0)) -> PM-012 | D17: =COUNTIF(Data!$C$2:$C$251,A17) -> 8 | E17: =SUMIF(Data!$C$2:$C$251,A17,Data!$H$2:$H$251) -> 27 | F17: =SUMIF(Data!$C$2:$C$251,A17,Data!$N$2:$N$251) -> 9799.73 | G17: =IF(D17=0,0,F17/D17) -> 1224.9662 | H17: =F17/SUM($F$6:$F$55) -> 0.042757644 | I17: =RANK(F17,$F$6:$F$55)+COUNTIF($F$6:F17,F17)-1 -> 4 | J17: =IF(F17>=$G$3,"High-Value","Regular") -> High-Value | K17: =SUMPRODUCT(MAX((Data!$C$2:$C$251=A17)*Data!$B$2:$B$251)) -> 45607 | L17: =TODAY()-K17 -> 718 | M17: =IF(COUNTIFS(Data!$C$2:$C$251,$A17,Data!$G$2:$G$251,"Electronics")>0,"Yes","No") -> Yes | N17: =IF(COUNTIFS(Data!$C$2:$C$251,$A17,Data!$G$2:$G$251,"Furniture")>0,"Yes","No") -> Yes | O17: =IF(COUNTIFS(Data!$C$2:$C$251,$A17,Data!$G$2:$G$251,"Appliances")>0,"Yes","No") -> No | P17: =(COUNTIFS(Data!$C$2:$C$251,A17,Data!$L$2:$L$251,"Basic")>0)+(COUNTIFS(Data!$C$2:$C$251,A17,Data!$L$2:$L$251,"Standard")>0)+(COUNTIFS(Data!$C$2:$C$251,A17,Data!$L$2:$L$251,"Premium")>0) -> 3
A18: CUST013 | B18: =INDEX(Data!$D$2:$D$251,MATCH(A18,Data!$C$2:$C$251,0)) -> Joseph Jackson | C18: =INDEX(Data!$S$2:$S$251,MATCH(A18,Data!$C$2:$C$251,0)) -> JJ-013 | D18: =COUNTIF(Data!$C$2:$C$251,A18) -> 5 | E18: =SUMIF(Data!$C$2:$C$251,A18,Data!$H$2:$H$251) -> 16 | F18: =SUMIF(Data!$C$2:$C$251,A18,Data!$N$2:$N$251) -> 6949.84 | G18: =IF(D18=0,0,F18/D18) -> 1389.968 | H18: =F18/SUM($F$6:$F$55) -> 0.03032316 | I18: =RANK(F18,$F$6:$F$55)+COUNTIF($F$6:F18,F18)-1 -> 10 | J18: =IF(F18>=$G$3,"High-Value","Regular") -> High-Value | K18: =SUMPRODUCT(MAX((Data!$C$2:$C$251=A18)*Data!$B$2:$B$251)) -> 45627 | L18: =TODAY()-K18 -> 698 | M18: =IF(COUNTIFS(Data!$C$2:$C$251,$A18,Data!$G$2:$G$251,"Electronics")>0,"Yes","No") -> Yes | N18: =IF(COUNTIFS(Data!$C$2:$C$251,$A18,Data!$G$2:$G$251,"Furniture")>0,"Yes","No") -> No | O18: =IF(COUNTIFS(Data!$C$2:$C$251,$A18,Data!$G$2:$G$251,"Appliances")>0,"Yes","No") -> No | P18: =(COUNTIFS(Data!$C$2:$C$251,A18,Data!$L$2:$L$251,"Basic")>0)+(COUNTIFS(Data!$C$2:$C$251,A18,Data!$L$2:$L$251,"Standard")>0)+(COUNTIFS(Data!$C$2:$C$251,A18,Data!$L$2:$L$251,"Premium")>0) -> 2
A19: CUST014 | B19: =INDEX(Data!$D$2:$D$251,MATCH(A19,Data!$C$2:$C$251,0)) -> Linda Martin | C19: =INDEX(Data!$S$2:$S$251,MATCH(A19,Data!$C$2:$C$251,0)) -> LM-014 | D19: =COUNTIF(Data!$C$2:$C$251,A19) -> 4 | E19: =SUMIF(Data!$C$2:$C$251,A19,Data!$H$2:$H$251) -> 10 | F19: =SUMIF(Data!$C$2:$C$251,A19,Data!$N$2:$N$251) -> 1289.9 | G19: =IF(D19=0,0,F19/D19) -> 322.475 | H19: =F19/SUM($F$6:$F$55) -> 0.0056280209 | I19: =RANK(F19,$F$6:$F$55)+COUNTIF($F$6:F19,F19)-1 -> 43 | J19: =IF(F19>=$G$3,"High-Value","Regular") -> Regular | K19: =SUMPRODUCT(MAX((Data!$C$2:$C$251=A19)*Data!$B$2:$B$251)) -> 45648 | L19: =TODAY()-K19 -> 677 | M19: =IF(COUNTIFS(Data!$C$2:$C$251,$A19,Data!$G$2:$G$251,"Electronics")>0,"Yes","No") -> Yes | N19: =IF(COUNTIFS(Data!$C$2:$C$251,$A19,Data!$G$2:$G$251,"Furniture")>0,"Yes","No") -> Yes | O19: =IF(COUNTIFS(Data!$C$2:$C$251,$A19,Data!$G$2:$G$251,"Appliances")>0,"Yes","No") -> Yes | P19: =(COUNTIFS(Data!$C$2:$C$251,A19,Data!$L$2:$L$251,"Basic")>0)+(COUNTIFS(Data!$C$2:$C$251,A19,Data!$L$2:$L$251,"Standard")>0)+(COUNTIFS(Data!$C$2:$C$251,A19,Data!$L$2:$L$251,"Premium")>0) -> 3
A20: CUST015 | B20: =INDEX(Data!$D$2:$D$251,MATCH(A20,Data!$C$2:$C$251,0)) -> Richard Lee | C20: =INDEX(Data!$S$2:$S$251,MATCH(A20,Data!$C$2:$C$251,0)) -> RL-015 | D20: =COUNTIF(Data!$C$2:$C$251,A20) -> 3 | E20: =SUMIF(Data!$C$2:$C$251,A20,Data!$H$2:$H$251) -> 7 | F20: =SUMIF(Data!$C$2:$C$251,A20,Data!$N$2:$N$251) -> 739.93 | G20: =IF(D20=0,0,F20/D20) -> 246.64333 | H20: =F20/SUM($F$6:$F$55) -> 0.0032284219 | I20: =RANK(F20,$F$6:$F$55)+COUNTIF($F$6:F20,F20)-1 -> 46 | J20: =IF(F20>=$G$3,"High-Value","Regular") -> Regular | K20: =SUMPRODUCT(MAX((Data!$C$2:$C$251=A20)*Data!$B$2:$B$251)) -> 45715 | L20: =TODAY()-K20 -> 610 | M20: =IF(COUNTIFS(Data!$C$2:$C$251,$A20,Data!$G$2:$G$251,"Electronics")>0,"Yes","No") -> No | N20: =IF(COUNTIFS(Data!$C$2:$C$251,$A20,Data!$G$2:$G$251,"Furniture")>0,"Yes","No") -> Yes | O20: =IF(COUNTIFS(Data!$C$2:$C$251,$A20,Data!$G$2:$G$251,"Appliances")>0,"Yes","No") -> Yes | P20: =(COUNTIFS(Data!$C$2:$C$251,A20,Data!$L$2:$L$251,"Basic")>0)+(COUNTIFS(Data!$C$2:$C$251,A20,Data!$L$2:$L$251,"Standard")>0)+(COUNTIFS(Data!$C$2:$C$251,A20,Data!$L$2:$L$251,"Premium")>0) -> 2
A21: CUST016 | B21: =INDEX(Data!$D$2:$D$251,MATCH(A21,Data!$C$2:$C$251,0)) -> Elizabeth Hall | C21: =INDEX(Data!$S$2:$S$251,MATCH(A21,Data!$C$2:$C$251,0)) -> EH-016 | D21: =COUNTIF(Data!$C$2:$C$251,A21) -> 4 | E21: =SUMIF(Data!$C$2:$C$251,A21,Data!$H$2:$H$251) -> 14 | F21: =SUMIF(Data!$C$2:$C$251,A21,Data!$N$2:$N$251) -> 3649.86 | G21: =IF(D21=0,0,F21/D21) -> 912.465 | H21: =F21/SUM($F$6:$F$55) -> 0.015924869 | I21: =RANK(F21,$F$6:$F$55)+COUNTIF($F$6:F21,F21)-1 -> 31 | J21: =IF(F21>=$G$3,"High-Value","Regular") -> Regular | K21: =SUMPRODUCT(MAX((Data!$C$2:$C$251=A21)*Data!$B$2:$B$251)) -> 45711 | L21: =TODAY()-K21 -> 614 | M21: =IF(COUNTIFS(Data!$C$2:$C$251,$A21,Data!$G$2:$G$251,"Electronics")>0,"Yes","No") -> Yes | N21: =IF(COUNTIFS(Data!$C$2:$C$251,$A21,Data!$G$2:$G$251,"Furniture")>0,"Yes","No") -> Yes | O21: =IF(COUNTIFS(Data!$C$2:$C$251,$A21,Data!$G$2:$G$251,"Appliances")>0,"Yes","No") -> No | P21: =(COUNTIFS(Data!$C$2:$C$251,A21,Data!$L$2:$L$251,"Basic")>0)+(COUNTIFS(Data!$C$2:$C$251,A21,Data!$L$2:$L$251,"Standard")>0)+(COUNTIFS(Data!$C$2:$C$251,A21,Data!$L$2:$L$251,"Premium")>0) -> 2
A22: CUST017 | B22: =INDEX(Data!$D$2:$D$251,MATCH(A22,Data!$C$2:$C$251,0)) -> Charles Allen | C22: =INDEX(Data!$S$2:$S$251,MATCH(A22,Data!$C$2:$C$251,0)) -> CA-017 | D22: =COUNTIF(Data!$C$2:$C$251,A22) -> 9 | E22: =SUMIF(Data!$C$2:$C$251,A22,Data!$H$2:$H$251) -> 27 | F22: =SUMIF(Data!$C$2:$C$251,A22,Data!$N$2:$N$251) -> 5089.73 | G22: =IF(D22=0,0,F22/D22) -> 565.52556 | H22: =F22/SUM($F$6:$F$55) -> 0.02220723 | I22: =RANK(F22,$F$6:$F$55)+COUNTIF($F$6:F22,F22)-1 -> 20 | J22: =IF(F22>=$G$3,"High-Value","Regular") -> Regular | K22: =SUMPRODUCT(MAX((Data!$C$2:$C$251=A22)*Data!$B$2:$B$251)) -> 45724 | L22: =TODAY()-K22 -> 601 | M22: =IF(COUNTIFS(Data!$C$2:$C$251,$A22,Data!$G$2:$G$251,"Electronics")>0,"Yes","No") -> Yes | N22: =IF(COUNTIFS(Data!$C$2:$C$251,$A22,Data!$G$2:$G$251,"Furniture")>0,"Yes","No") -> Yes | O22: =IF(COUNTIFS(Data!$C$2:$C$251,$A22,Data!$G$2:$G$251,"Appliances")>0,"Yes","No") -> Yes | P22: =(COUNTIFS(Data!$C$2:$C$251,A22,Data!$L$2:$L$251,"Basic")>0)+(COUNTIFS(Data!$C$2:$C$251,A22,Data!$L$2:$L$251,"Standard")>0)+(COUNTIFS(Data!$C$2:$C$251,A22,Data!$L$2:$L$251,"Premium")>0) -> 3
A23: CUST018 | B23: =INDEX(Data!$D$2:$D$251,MATCH(A23,Data!$C$2:$C$251,0)) -> Barbara Young | C23: =INDEX(Data!$S$2:$S$251,MATCH(A23,Data!$C$2:$C$251,0)) -> BY-018 | D23: =COUNTIF(Data!$C$2:$C$251,A23) -> 5 | E23: =SUMIF(Data!$C$2:$C$251,A23,Data!$H$2:$H$251) -> 20 | F23: =SUMIF(Data!$C$2:$C$251,A23,Data!$N$2:$N$251) -> 10649.8 | G23: =IF(D23=0,0,F23/D23) -> 2129.96 | H23: =F23/SUM($F$6:$F$55) -> 0.046466623 | I23: =RANK(F23,$F$6:$F$55)+COUNTIF($F$6:F23,F23)-1 -> 3 | J23: =IF(F23>=$G$3,"High-Value","Regular") -> High-Value | K23: =SUMPRODUCT(MAX((Data!$C$2:$C$251=A23)*Data!$B$2:$B$251)) -> 45708 | L23: =TODAY()-K23 -> 617 | M23: =IF(COUNTIFS(Data!$C$2:$C$251,$A23,Data!$G$2:$G$251,"Electronics")>0,"Yes","No") -> Yes | N23: =IF(COUNTIFS(Data!$C$2:$C$251,$A23,Data!$G$2:$G$251,"Furniture")>0,"Yes","No") -> No | O23: =IF(COUNTIFS(Data!$C$2:$C$251,$A23,Data!$G$2:$G$251,"Appliances")>0,"Yes","No") -> No | P23: =(COUNTIFS(Data!$C$2:$C$251,A23,Data!$L$2:$L$251,"Basic")>0)+(COUNTIFS(Data!$C$2:$C$251,A23,Data!$L$2:$L$251,"Standard")>0)+(COUNTIFS(Data!$C$2:$C$251,A23,Data!$L$2:$L$251,"Premium")>0) -> 3
A24: CUST019 | B24: =INDEX(Data!$D$2:$D$251,MATCH(A24,Data!$C$2:$C$251,0)) -> Daniel King | C24: =INDEX(Data!$S$2:$S$251,MATCH(A24,Data!$C$2:$C$251,0)) -> DK-019 | D24: =COUNTIF(Data!$C$2:$C$251,A24) -> 7 | E24: =SUMIF(Data!$C$2:$C$251,A24,Data!$H$2:$H$251) -> 20 | F24: =SUMIF(Data!$C$2:$C$251,A24,Data!$N$2:$N$251) -> 7309.8 | G24: =IF(D24=0,0,F24/D24) -> 1044.2571 | H24: =F24/SUM($F$6:$F$55) -> 0.031893718 | I24: =RANK(F24,$F$6:$F$55)+COUNTIF($F$6:F24,F24)-1 -> 8 | J24: =IF(F24>=$G$3,"High-Value","Regular") -> High-Value | K24: =SUMPRODUCT(MAX((Data!$C$2:$C$251=A24)*Data!$B$2:$B$251)) -> 45660 | L24: =TODAY()-K24 -> 665 | M24: =IF(COUNTIFS(Data!$C$2:$C$251,$A24,Data!$G$2:$G$251,"Electronics")>0,"Yes","No") -> Yes | N24: =IF(COUNTIFS(Data!$C$2:$C$251,$A24,Data!$G$2:$G$251,"Furniture")>0,"Yes","No") -> Yes | O24: =IF(COUNTIFS(Data!$C$2:$C$251,$A24,Data!$G$2:$G$251,"Appliances")>0,"Yes","No") -> Yes | P24: =(COUNTIFS(Data!$C$2:$C$251,A24,Data!$L$2:$L$251,"Basic")>0)+(COUNTIFS(Data!$C$2:$C$251,A24,Data!$L$2:$L$251,"Standard")>0)+(COUNTIFS(Data!$C$2:$C$251,A24,Data!$L$2:$L$251,"Premium")>0) -> 3
A25: CUST020 | B25: =INDEX(Data!$D$2:$D$251,MATCH(A25,Data!$C$2:$C$251,0)) -> Margaret Wright | C25: =INDEX(Data!$S$2:$S$251,MATCH(A25,Data!$C$2:$C$251,0)) -> MW-020 | D25: =COUNTIF(Data!$C$2:$C$251,A25) -> 4 | E25: =SUMIF(Data!$C$2:$C$251,A25,Data!$H$2:$H$251) -> 12 | F25: =SUMIF(Data!$C$2:$C$251,A25,Data!$N$2:$N$251) -> 2099.88 | G25: =IF(D25=0,0,F25/D25) -> 524.97 | H25: =F25/SUM($F$6:$F$55) -> 0.0091620811 | I25: =RANK(F25,$F$6:$F$55)+COUNTIF($F$6:F25,F25)-1 -> 35 | J25: =IF(F25>=$G$3,"High-Value","Regular") -> Regular | K25: =SUMPRODUCT(MAX((Data!$C$2:$C$251=A25)*Data!$B$2:$B$251)) -> 45745 | L25: =TODAY()-K25 -> 580 | M25: =IF(COUNTIFS(Data!$C$2:$C$251,$A25,Data!$G$2:$G$251,"Electronics")>0,"Yes","No") -> Yes | N25: =IF(COUNTIFS(Data!$C$2:$C$251,$A25,Data!$G$2:$G$251,"Furniture")>0,"Yes","No") -> Yes | O25: =IF(COUNTIFS(Data!$C$2:$C$251,$A25,Data!$G$2:$G$251,"Appliances")>0,"Yes","No") -> No | P25: =(COUNTIFS(Data!$C$2:$C$251,A25,Data!$L$2:$L$251,"Basic")>0)+(COUNTIFS(Data!$C$2:$C$251,A25,Data!$L$2:$L$251,"Standard")>0)+(COUNTIFS(Data!$C$2:$C$251,A25,Data!$L$2:$L$251,"Premium")>0) -> 2
A26: CUST021 | B26: =INDEX(Data!$D$2:$D$251,MATCH(A26,Data!$C$2:$C$251,0)) -> Kevin Scott | C26: =INDEX(Data!$S$2:$S$251,MATCH(A26,Data!$C$2:$C$251,0)) -> KS-021 | D26: =COUNTIF(Data!$C$2:$C$251,A26) -> 6 | E26: =SUMIF(Data!$C$2:$C$251,A26,Data!$H$2:$H$251) -> 13 | F26: =SUMIF(Data!$C$2:$C$251,A26,Data!$N$2:$N$251) -> 3259.87 | G26: =IF(D26=0,0,F26/D26) -> 543.31167 | H26: =F26/SUM($F$6:$F$55) -> 0.014223286 | I26: =RANK(F26,$F$6:$F$55)+COUNTIF($F$6:F26,F26)-1 -> 33 | J26: =IF(F26>=$G$3,"High-Value","Regular") -> Regular | K26: =SUMPRODUCT(MAX((Data!$C$2:$C$251=A26)*Data!$B$2:$B$251)) -> 45704 | L26: =TODAY()-K26 -> 621 | M26: =IF(COUNTIFS(Data!$C$2:$C$251,$A26,Data!$G$2:$G$251,"Electronics")>0,"Yes","No") -> Yes | N26: =IF(COUNTIFS(Data!$C$2:$C$251,$A26,Data!$G$2:$G$251,"Furniture")>0,"Yes","No") -> Yes | O26: =IF(COUNTIFS(Data!$C$2:$C$251,$A26,Data!$G$2:$G$251,"Appliances")>0,"Yes","No") -> Yes | P26: =(COUNTIFS(Data!$C$2:$C$251,A26,Data!$L$2:$L$251,"Basic")>0)+(COUNTIFS(Data!$C$2:$C$251,A26,Data!$L$2:$L$251,"Standard")>0)+(COUNTIFS(Data!$C$2:$C$251,A26,Data!$L$2:$L$251,"Premium")>0) -> 3
A27: CUST022 | B27: =INDEX(Data!$D$2:$D$251,MATCH(A27,Data!$C$2:$C$251,0)) -> Susan Green | C27: =INDEX(Data!$S$2:$S$251,MATCH(A27,Data!$C$2:$C$251,0)) -> SG-022 | D27: =COUNTIF(Data!$C$2:$C$251,A27) -> 4 | E27: =SUMIF(Data!$C$2:$C$251,A27,Data!$H$2:$H$251) -> 11 | F27: =SUMIF(Data!$C$2:$C$251,A27,Data!$N$2:$N$251) -> 1979.89 | G27: =IF(D27=0,0,F27/D27) -> 494.9725 | H27: =F27/SUM($F$6:$F$55) -> 0.0086385473 | I27: =RANK(F27,$F$6:$F$55)+COUNTIF($F$6:F27,F27)-1 -> 37 | J27: =IF(F27>=$G$3,"High-Value","Regular") -> Regular | K27: =SUMPRODUCT(MAX((Data!$C$2:$C$251=A27)*Data!$B$2:$B$251)) -> 45682 | L27: =TODAY()-K27 -> 643 | M27: =IF(COUNTIFS(Data!$C$2:$C$251,$A27,Data!$G$2:$G$251,"Electronics")>0,"Yes","No") -> Yes | N27: =IF(COUNTIFS(Data!$C$2:$C$251,$A27,Data!$G$2:$G$251,"Furniture")>0,"Yes","No") -> Yes | O27: =IF(COUNTIFS(Data!$C$2:$C$251,$A27,Data!$G$2:$G$251,"Appliances")>0,"Yes","No") -> Yes | P27: =(COUNTIFS(Data!$C$2:$C$251,A27,Data!$L$2:$L$251,"Basic")>0)+(COUNTIFS(Data!$C$2:$C$251,A27,Data!$L$2:$L$251,"Standard")>0)+(COUNTIFS(Data!$C$2:$C$251,A27,Data!$L$2:$L$251,"Premium")>0) -> 2
... A55: CUST050 | B55: =INDEX(Data!$D$2:$D$251,MATCH(A55,Data!$C$2:$C$251,0)) -> Julie Foster | C55: =INDEX(Data!$S$2:$S$251,MATCH(A55,Data!$C$2:$C$251,0)) -> JF-050 | D55: =COUNTIF(Data!$C$2:$C$251,A55) -> 1 | E55: =SUMIF(Data!$C$2:$C$251,A55,Data!$H$2:$H$251) -> 4 | F55: =SUMIF(Data!$C$2:$C$251,A55,Data!$N$2:$N$251) -> 239.96 | G55: =IF(D55=0,0,F55/D55) -> 239.96 | H55: =F55/SUM($F$6:$F$55) -> 0.0010469803 | I55: =RANK(F55,$F$6:$F$55)+COUNTIF($F$6:F55,F55)-1 -> 49 | J55: =IF(F55>=$G$3,"High-Value","Regular") -> Regular | K55: =SUMPRODUCT(MAX((Data!$C$2:$C$251=A55)*Data!$B$2:$B$251)) -> 45452 | L55: =TODAY()-K55 -> 873 | M55: =IF(COUNTIFS(Data!$C$2:$C$251,$A55,Data!$G$2:$G$251,"Electronics")>0,"Yes","No") -> No | N55: =IF(COUNTIFS(Data!$C$2:$C$251,$A55,Data!$G$2:$G$251,"Furniture")>0,"Yes","No") -> No | O55: =IF(COUNTIFS(Data!$C$2:$C$251,$A55,Data!$G$2:$G$251,"Appliances")>0,"Yes","No") -> Yes | P55: =(COUNTIFS(Data!$C$2:$C$251,A55,Data!$L$2:$L$251,"Basic")>0)+(COUNTIFS(Data!$C$2:$C$251,A55,Data!$L$2:$L$251,"Standard")>0)+(COUNTIFS(Data!$C$2:$C$251,A55,Data!$L$2:$L$251,"Premium")>0) -> 1
A57: Most frequent (repeating) customer | D57: =INDEX(B6:B55,MATCH(MAX(D6:D55),D6:D55,0)) -> Mark Carter | F57: =MAX(D6:D55) -> 12 | G57: orders
A58: High-value customers | D58: =COUNTIF(J6:J55,"High-Value") -> 10
A59: Revenue share of high-value group | D59: =SUMIF(J6:J55,"High-Value",F6:F55)/SUM(F6:F55) -> 0.40955822
A60: Customers who bought BOTH Electronics and Furniture | D60: =COUNTIFS(M6:M55,"Yes",N6:N55,"Yes") -> 34

Sheet Timestamp
A1: Timestamps - NOW, TODAY and a self-freezing timestamp
A2: Iterative calculation is switched on in this file (File > Options > Formulas > Enable iterative calculation).
A4: Live clock (NOW) | B4: =NOW() -> 46325.374
A5: Today (TODAY) | B5: =TODAY() -> 46325
A6: Latest transaction in data | B6: =MAX(Data!$B$2:$B$251) -> 45758
A7: Days since latest transaction | B7: =B5-B6 -> 567
A8: Data span (years, months, days) | B8: =DATEDIF(MIN(Data!$B$2:$B$251),B6,"y")&"y "&DATEDIF(MIN(Data!$B$2:$B$251),B6,"ym")&"m "&DATEDIF(MIN(Data!$B$2:$B$251),B6,"md")&"d" -> 1y 0m 0d
A10: Self-freezing timestamp (iterative)
A11: Entry (type anything) | B11: Timestamp frozen when entry typed
B12: =IF(A12<>"",IF(B12="",NOW(),B12),"")
B13: =IF(A13<>"",IF(B13="",NOW(),B13),"")
B14: =IF(A14<>"",IF(B14="",NOW(),B14),"")
B15: =IF(A15<>"",IF(B15="",NOW(),B15),"")
B16: =IF(A16<>"",IF(B16="",NOW(),B16),"")
A18: How it works: B refers to itself. Once NOW() is stored it keeps its own old value, so it stops changing. Delete the entry to reset.

Sheet Analysis
A1: Product, Category, Region and Payment Analysis
A3: Product_ID | B3: Product | C3: Category | D3: Unit Price | E3: Orders | F3: Units | G3: Revenue | H3: % of Revenue
A4: P001 | B4: =INDEX(Data!$F$2:$F$251,MATCH(A4,Data!$E$2:$E$251,0)) -> Laptop | C4: =INDEX(Data!$G$2:$G$251,MATCH(A4,Data!$E$2:$E$251,0)) -> Electronics | D4: =INDEX(Data!$I$2:$I$251,MATCH(A4,Data!$E$2:$E$251,0)) -> 899.99 | E4: =COUNTIF(Data!$E$2:$E$251,A4) -> 24 | F4: =SUMIF(Data!$E$2:$E$251,A4,Data!$H$2:$H$251) -> 75 | G4: =SUMIF(Data!$E$2:$E$251,A4,Data!$N$2:$N$251) -> 67499.25 | H4: =G4/SUM($G$4:$G$13) -> 0.29450902
A5: P002 | B5: =INDEX(Data!$F$2:$F$251,MATCH(A5,Data!$E$2:$E$251,0)) -> Smartphone | C5: =INDEX(Data!$G$2:$G$251,MATCH(A5,Data!$E$2:$E$251,0)) -> Electronics | D5: =INDEX(Data!$I$2:$I$251,MATCH(A5,Data!$E$2:$E$251,0)) -> 699.99 | E5: =COUNTIF(Data!$E$2:$E$251,A5) -> 31 | F5: =SUMIF(Data!$E$2:$E$251,A5,Data!$H$2:$H$251) -> 96 | G5: =SUMIF(Data!$E$2:$E$251,A5,Data!$N$2:$N$251) -> 67199.04 | H5: =G5/SUM($G$4:$G$13) -> 0.29319916
A6: P003 | B6: =INDEX(Data!$F$2:$F$251,MATCH(A6,Data!$E$2:$E$251,0)) -> Headphones | C6: =INDEX(Data!$G$2:$G$251,MATCH(A6,Data!$E$2:$E$251,0)) -> Electronics | D6: =INDEX(Data!$I$2:$I$251,MATCH(A6,Data!$E$2:$E$251,0)) -> 149.99 | E6: =COUNTIF(Data!$E$2:$E$251,A6) -> 16 | F6: =SUMIF(Data!$E$2:$E$251,A6,Data!$H$2:$H$251) -> 47 | G6: =SUMIF(Data!$E$2:$E$251,A6,Data!$N$2:$N$251) -> 7049.53 | H6: =G6/SUM($G$4:$G$13) -> 0.030758122
A7: P004 | B7: =INDEX(Data!$F$2:$F$251,MATCH(A7,Data!$E$2:$E$251,0)) -> Coffee Maker | C7: =INDEX(Data!$G$2:$G$251,MATCH(A7,Data!$E$2:$E$251,0)) -> Appliances | D7: =INDEX(Data!$I$2:$I$251,MATCH(A7,Data!$E$2:$E$251,0)) -> 79.99 | E7: =COUNTIF(Data!$E$2:$E$251,A7) -> 14 | F7: =SUMIF(Data!$E$2:$E$251,A7,Data!$H$2:$H$251) -> 39 | G7: =SUMIF(Data!$E$2:$E$251,A7,Data!$N$2:$N$251) -> 3119.61 | H7: =G7/SUM($G$4:$G$13) -> 0.013611311
A8: P005 | B8: =INDEX(Data!$F$2:$F$251,MATCH(A8,Data!$E$2:$E$251,0)) -> Blender | C8: =INDEX(Data!$G$2:$G$251,MATCH(A8,Data!$E$2:$E$251,0)) -> Appliances | D8: =INDEX(Data!$I$2:$I$251,MATCH(A8,Data!$E$2:$E$251,0)) -> 59.99 | E8: =COUNTIF(Data!$E$2:$E$251,A8) -> 29 | F8: =SUMIF(Data!$E$2:$E$251,A8,Data!$H$2:$H$251) -> 87 | G8: =SUMIF(Data!$E$2:$E$251,A8,Data!$N$2:$N$251) -> 5219.13 | H8: =G8/SUM($G$4:$G$13) -> 0.022771821
A9: P006 | B9: =INDEX(Data!$F$2:$F$251,MATCH(A9,Data!$E$2:$E$251,0)) -> Office Chair | C9: =INDEX(Data!$G$2:$G$251,MATCH(A9,Data!$E$2:$E$251,0)) -> Furniture | D9: =INDEX(Data!$I$2:$I$251,MATCH(A9,Data!$E$2:$E$251,0)) -> 199.99 | E9: =COUNTIF(Data!$E$2:$E$251,A9) -> 15 | F9: =SUMIF(Data!$E$2:$E$251,A9,Data!$H$2:$H$251) -> 52 | G9: =SUMIF(Data!$E$2:$E$251,A9,Data!$N$2:$N$251) -> 10399.48 | H9: =G9/SUM($G$4:$G$13) -> 0.04537444
A10: P007 | B10: =INDEX(Data!$F$2:$F$251,MATCH(A10,Data!$E$2:$E$251,0)) -> Desk | C10: =INDEX(Data!$G$2:$G$251,MATCH(A10,Data!$E$2:$E$251,0)) -> Furniture | D10: =INDEX(Data!$I$2:$I$251,MATCH(A10,Data!$E$2:$E$251,0)) -> 299.99 | E10: =COUNTIF(Data!$E$2:$E$251,A10) -> 26 | F10: =SUMIF(Data!$E$2:$E$251,A10,Data!$H$2:$H$251) -> 78 | G10: =SUMIF(Data!$E$2:$E$251,A10,Data!$N$2:$N$251) -> 23399.22 | H10: =G10/SUM($G$4:$G$13) -> 0.10209419
A11: P008 | B11: =INDEX(Data!$F$2:$F$251,MATCH(A11,Data!$E$2:$E$251,0)) -> Bookshelf | C11: =INDEX(Data!$G$2:$G$251,MATCH(A11,Data!$E$2:$E$251,0)) -> Furniture | D11: =INDEX(Data!$I$2:$I$251,MATCH(A11,Data!$E$2:$E$251,0)) -> 149.99 | E11: =COUNTIF(Data!$E$2:$E$251,A11) -> 35 | F11: =SUMIF(Data!$E$2:$E$251,A11,Data!$H$2:$H$251) -> 102 | G11: =SUMIF(Data!$E$2:$E$251,A11,Data!$N$2:$N$251) -> 15298.98 | H11: =G11/SUM($G$4:$G$13) -> 0.066751669
A12: P009 | B12: =INDEX(Data!$F$2:$F$251,MATCH(A12,Data!$E$2:$E$251,0)) -> Monitor | C12: =INDEX(Data!$G$2:$G$251,MATCH(A12,Data!$E$2:$E$251,0)) -> Electronics | D12: =INDEX(Data!$I$2:$I$251,MATCH(A12,Data!$E$2:$E$251,0)) -> 249.99 | E12: =COUNTIF(Data!$E$2:$E$251,A12) -> 26 | F12: =SUMIF(Data!$E$2:$E$251,A12,Data!$H$2:$H$251) -> 88 | G12: =SUMIF(Data!$E$2:$E$251,A12,Data!$N$2:$N$251) -> 21999.12 | H12: =G12/SUM($G$4:$G$13) -> 0.095985352
A13: P010 | B13: =INDEX(Data!$F$2:$F$251,MATCH(A13,Data!$E$2:$E$251,0)) -> Keyboard | C13: =INDEX(Data!$G$2:$G$251,MATCH(A13,Data!$E$2:$E$251,0)) -> Electronics | D13: =INDEX(Data!$I$2:$I$251,MATCH(A13,Data!$E$2:$E$251,0)) -> 89.99 | E13: =COUNTIF(Data!$E$2:$E$251,A13) -> 34 | F13: =SUMIF(Data!$E$2:$E$251,A13,Data!$H$2:$H$251) -> 89 | G13: =SUMIF(Data!$E$2:$E$251,A13,Data!$N$2:$N$251) -> 8009.11 | H13: =G13/SUM($G$4:$G$13) -> 0.034944909
A15: Most frequently purchased product (by orders) | E15: =INDEX(B4:B13,MATCH(MAX(E4:E13),E4:E13,0)) -> Bookshelf | G15: =MAX(E4:E13) -> 35
A16: Most units sold | E16: =INDEX(B4:B13,MATCH(MAX(F4:F13),F4:F13,0)) -> Bookshelf | G16: =MAX(F4:F13) -> 102
A17: Highest revenue product | E17: =INDEX(B4:B13,MATCH(MAX(G4:G13),G4:G13,0)) -> Laptop | G17: =MAX(G4:G13) -> 67499.25
A20: Category | B20: Orders | C20: Revenue | D20: % of Revenue
A21: Electronics | B21: =COUNTIF(Data!$G$2:$G$251,A21) -> 131 | C21: =SUMIF(Data!$G$2:$G$251,A21,Data!$N$2:$N$251) -> 171756.05 | D21: =C21/SUM(C$21:C$23) -> 0.74939657
A22: Furniture | B22: =COUNTIF(Data!$G$2:$G$251,A22) -> 76 | C22: =SUMIF(Data!$G$2:$G$251,A22,Data!$N$2:$N$251) -> 49097.68 | D22: =C22/SUM(C$21:C$23) -> 0.2142203
A23: Appliances | B23: =COUNTIF(Data!$G$2:$G$251,A23) -> 43 | C23: =SUMIF(Data!$G$2:$G$251,A23,Data!$N$2:$N$251) -> 8338.74 | D23: =C23/SUM(C$21:C$23) -> 0.036383132
A26: Region | B26: Orders | C26: Revenue | D26: % of Revenue
A27: North | B27: =COUNTIF(Data!$K$2:$K$251,A27) -> 59 | C27: =SUMIF(Data!$K$2:$K$251,A27,Data!$N$2:$N$251) -> 50808.31 | D27: =C27/SUM(C$27:C$31) -> 0.22168403
A28: South | B28: =COUNTIF(Data!$K$2:$K$251,A28) -> 42 | C28: =SUMIF(Data!$K$2:$K$251,A28,Data!$N$2:$N$251) -> 36398.75 | D28: =C28/SUM(C$27:C$31) -> 0.15881303
A29: East | B29: =COUNTIF(Data!$K$2:$K$251,A29) -> 48 | C29: =SUMIF(Data!$K$2:$K$251,A29,Data!$N$2:$N$251) -> 59288.39 | D29: =C29/SUM(C$27:C$31) -> 0.25868385
A30: West | B30: =COUNTIF(Data!$K$2:$K$251,A30) -> 47 | C30: =SUMIF(Data!$K$2:$K$251,A30,Data!$N$2:$N$251) -> 41408.68 | D30: =C30/SUM(C$27:C$31) -> 0.18067208
A31: Central | B31: =COUNTIF(Data!$K$2:$K$251,A31) -> 54 | C31: =SUMIF(Data!$K$2:$K$251,A31,Data!$N$2:$N$251) -> 41288.34 | D31: =C31/SUM(C$27:C$31) -> 0.18014702
A34: Payment Method | B34: Orders | C34: Revenue | D34: % of Revenue
A35: Cash | B35: =COUNTIF(Data!$J$2:$J$251,A35) -> 76 | C35: =SUMIF(Data!$J$2:$J$251,A35,Data!$N$2:$N$251) -> 57427.79 | D35: =C35/SUM(C$35:C$38) -> 0.25056578
A36: Credit Card | B36: =COUNTIF(Data!$J$2:$J$251,A36) -> 68 | C36: =SUMIF(Data!$J$2:$J$251,A36,Data!$N$2:$N$251) -> 61447.96 | D36: =C36/SUM(C$35:C$38) -> 0.26810636
A37: Debit Card | B37: =COUNTIF(Data!$J$2:$J$251,A37) -> 54 | C37: =SUMIF(Data!$J$2:$J$251,A37,Data!$N$2:$N$251) -> 52118.31 | D37: =C37/SUM(C$35:C$38) -> 0.22739975
A38: PayPal | B38: =COUNTIF(Data!$J$2:$J$251,A38) -> 52 | C38: =SUMIF(Data!$J$2:$J$251,A38,Data!$N$2:$N$251) -> 58198.41 | D38: =C38/SUM(C$35:C$38) -> 0.25392811
A41: Customer Segment | B41: Orders | C41: Revenue | D41: % of Revenue
A42: Basic | B42: =COUNTIF(Data!$L$2:$L$251,A42) -> 74 | C42: =SUMIF(Data!$L$2:$L$251,A42,Data!$N$2:$N$251) -> 62177.81 | D42: =C42/SUM(C$42:C$44) -> 0.27129081
A43: Standard | B43: =COUNTIF(Data!$L$2:$L$251,A43) -> 81 | C43: =SUMIF(Data!$L$2:$L$251,A43,Data!$N$2:$N$251) -> 82357.54 | D43: =C43/SUM(C$42:C$44) -> 0.3593379
A44: Premium | B44: =COUNTIF(Data!$L$2:$L$251,A44) -> 95 | C44: =SUMIF(Data!$L$2:$L$251,A44,Data!$N$2:$N$251) -> 84657.12 | D44: =C44/SUM(C$42:C$44) -> 0.3693713

Sheet Monthly_Trend
A1: Monthly Trend, Regression and Forecast
A2: Start month | B2: 45383
A4: Month End | B4: Month | C4: Revenue | D4: Orders | E4: MoM % Change | F4: t (month #) | G4: Included in Regression? | H4: Fitted (trend)
A5: =EOMONTH($B$2,0) -> 45412 | B5: =TEXT(A5,"mmm yyyy") -> Apr 2024 | C5: =SUMIFS(Data!$N$2:$N$251,Data!$O$2:$O$251,A5) -> 20919.33 | D5: =COUNTIFS(Data!$O$2:$O$251,A5) -> 21 | F5: 1 | G5: No (partial) | H5: =$B$21+$B$20*F5 -> 16269.276
A6: =EOMONTH(A5,1) -> 45443 | B6: =TEXT(A6,"mmm yyyy") -> May 2024 | C6: =SUMIFS(Data!$N$2:$N$251,Data!$O$2:$O$251,A6) -> 17039.35 | D6: =COUNTIFS(Data!$O$2:$O$251,A6) -> 19 | E6: =IF(C5=0,0,C6/C5-1) -> -0.18547344 | F6: 2 | G6: Yes | H6: =$B$21+$B$20*F6 -> 16607.629
A7: =EOMONTH(A6,1) -> 45473 | B7: =TEXT(A7,"mmm yyyy") -> Jun 2024 | C7: =SUMIFS(Data!$N$2:$N$251,Data!$O$2:$O$251,A7) -> 19299.45 | D7: =COUNTIFS(Data!$O$2:$O$251,A7) -> 19 | E7: =IF(C6=0,0,C7/C6-1) -> 0.13264004 | F7: 3 | G7: Yes | H7: =$B$21+$B$20*F7 -> 16945.981
A8: =EOMONTH(A7,1) -> 45504 | B8: =TEXT(A8,"mmm yyyy") -> Jul 2024 | C8: =SUMIFS(Data!$N$2:$N$251,Data!$O$2:$O$251,A8) -> 18479.4 | D8: =COUNTIFS(Data!$O$2:$O$251,A8) -> 24 | E8: =IF(C7=0,0,C8/C7-1) -> -0.042490848 | F8: 4 | G8: Yes | H8: =$B$21+$B$20*F8 -> 17284.334
A9: =EOMONTH(A8,1) -> 45535 | B9: =TEXT(A9,"mmm yyyy") -> Aug 2024 | C9: =SUMIFS(Data!$N$2:$N$251,Data!$O$2:$O$251,A9) -> 15759.43 | D9: =COUNTIFS(Data!$O$2:$O$251,A9) -> 18 | E9: =IF(C8=0,0,C9/C8-1) -> -0.1471893 | F9: 5 | G9: Yes | H9: =$B$21+$B$20*F9 -> 17622.687
A10: =EOMONTH(A9,1) -> 45565 | B10: =TEXT(A10,"mmm yyyy") -> Sep 2024 | C10: =SUMIFS(Data!$N$2:$N$251,Data!$O$2:$O$251,A10) -> 12989.51 | D10: =COUNTIFS(Data!$O$2:$O$251,A10) -> 19 | E10: =IF(C9=0,0,C10/C9-1) -> -0.1757627 | F10: 6 | G10: Yes | H10: =$B$21+$B$20*F10 -> 17961.039
A11: =EOMONTH(A10,1) -> 45596 | B11: =TEXT(A11,"mmm yyyy") -> Oct 2024 | C11: =SUMIFS(Data!$N$2:$N$251,Data!$O$2:$O$251,A11) -> 20609.52 | D11: =COUNTIFS(Data!$O$2:$O$251,A11) -> 16 | E11: =IF(C10=0,0,C11/C10-1) -> 0.58662798 | F11: 7 | G11: Yes | H11: =$B$21+$B$20*F11 -> 18299.392
A12: =EOMONTH(A11,1) -> 45626 | B12: =TEXT(A12,"mmm yyyy") -> Nov 2024 | C12: =SUMIFS(Data!$N$2:$N$251,Data!$O$2:$O$251,A12) -> 12309.44 | D12: =COUNTIFS(Data!$O$2:$O$251,A12) -> 17 | E12: =IF(C11=0,0,C12/C11-1) -> -0.40273039 | F12: 8 | G12: Yes | H12: =$B$21+$B$20*F12 -> 18637.744
A13: =EOMONTH(A12,1) -> 45657 | B13: =TEXT(A13,"mmm yyyy") -> Dec 2024 | C13: =SUMIFS(Data!$N$2:$N$251,Data!$O$2:$O$251,A13) -> 23039.3 | D13: =COUNTIFS(Data!$O$2:$O$251,A13) -> 25 | E13: =IF(C12=0,0,C13/C12-1) -> 0.87167735 | F13: 9 | G13: Yes | H13: =$B$21+$B$20*F13 -> 18976.097
A14: =EOMONTH(A13,1) -> 45688 | B14: =TEXT(A14,"mmm yyyy") -> Jan 2025 | C14: =SUMIFS(Data!$N$2:$N$251,Data!$O$2:$O$251,A14) -> 25799.15 | D14: =COUNTIFS(Data!$O$2:$O$251,A14) -> 26 | E14: =IF(C13=0,0,C14/C13-1) -> 0.1197888 | F14: 10 | G14: Yes | H14: =$B$21+$B$20*F14 -> 19314.45
A15: =EOMONTH(A14,1) -> 45716 | B15: =TEXT(A15,"mmm yyyy") -> Feb 2025 | C15: =SUMIFS(Data!$N$2:$N$251,Data!$O$2:$O$251,A15) -> 16069.38 | D15: =COUNTIFS(Data!$O$2:$O$251,A15) -> 20 | E15: =IF(C14=0,0,C15/C14-1) -> -0.37713529 | F15: 11 | G15: Yes | H15: =$B$21+$B$20*F15 -> 19652.802
A16: =EOMONTH(A15,1) -> 45747 | B16: =TEXT(A16,"mmm yyyy") -> Mar 2025 | C16: =SUMIFS(Data!$N$2:$N$251,Data!$O$2:$O$251,A16) -> 19899.38 | D16: =COUNTIFS(Data!$O$2:$O$251,A16) -> 19 | E16: =IF(C15=0,0,C16/C15-1) -> 0.23834149 | F16: 12 | G16: Yes | H16: =$B$21+$B$20*F16 -> 19991.155
A17: =EOMONTH(A16,1) -> 45777 | B17: =TEXT(A17,"mmm yyyy") -> Apr 2025 | C17: =SUMIFS(Data!$N$2:$N$251,Data!$O$2:$O$251,A17) -> 6979.83 | D17: =COUNTIFS(Data!$O$2:$O$251,A17) -> 7 | E17: =IF(C16=0,0,C17/C16-1) -> -0.64924385 | F17: 13 | G17: No (partial) | H17: =$B$21+$B$20*F17 -> 20329.508
A19: Linear regression (Revenue = a + b * t), full months t=2..12
A20: Slope b (revenue per month) | B20: =SLOPE(C6:C16,F6:F16) -> 338.35264
A21: Intercept a | B21: =INTERCEPT(C6:C16,F6:F16) -> 15930.923
A22: R squared | B22: =RSQ(C6:C16,F6:F16) -> 0.076447365
A23: Std error of estimate | B23: =STEYX(C6:C16,F6:F16) -> 4111.4425
A24: Trend reading | B24: =IF(B22<0.3,"Weak trend - revenue is mostly seasonal/noisy",IF(B20>0,"Upward trend","Downward trend")) -> Weak trend - revenue is mostly seasonal/noisy
A26: Forecast | B26: t | C26: Forecast revenue
A27: =TEXT(EOMONTH($A$17,0),"mmm yyyy") -> Apr 2025 | B27: 14 | C27: =$B$21+$B$20*B27 -> 20667.86
A28: =TEXT(EOMONTH($A$17,1),"mmm yyyy") -> May 2025 | B28: 15 | C28: =$B$21+$B$20*B28 -> 21006.213
A29: =TEXT(EOMONTH($A$17,2),"mmm yyyy") -> Jun 2025 | B29: 16 | C29: =$B$21+$B$20*B29 -> 21344.566
A30: Forecast uses t=14,15,16 (May-Jul 2025) - the month after the last month in the data.

Sheet WhatIf
A1: What-If Analysis - Scenario Manager and Goal Seek
A3: Inputs (Scenario Manager changing cells)
A4: Price change % | B4: 0
A5: Volume change % | B5: 0
A6: Discount % | B6: 0
A8: Base revenue (all data) | B8: =SUM(Data!$N$2:$N$251) -> 229192.47
A9: Scenario revenue | B9: =B8*(1+B4)*(1+B5)*(1-B6) -> 229192.47
A10: Change vs base | B10: =B9-B8 -> 0
A11: Change vs base % | B11: =B9/B8-1 -> 0
A13: Goal Seek setup
A14: Target revenue (typed value) | B14: 250000 | C14: Assumption: target is a round number set by the analyst; change it freely.
A15: Goal Seek: Set cell B10 / To value B15 / By changing B5
A16: Check - exact price change needed (algebra) | B16: =B14/(B8*(1+B5)*(1-B6))-1 -> 0.090786272
A18: Scenario comparison (pre-built, formula driven)
A19: Scenario | B19: Price % | C19: Volume % | D19: Discount % | E19: Revenue | F19: vs Base
A20: Base | B20: 0 | C20: 0 | D20: 0 | E20: =$B$8*(1+B20)*(1+C20)*(1-D20) -> 229192.47 | F20: =E20/$B$8-1 -> 0
A21: Optimistic | B21: 0.05 | C21: 0.1 | D21: 0 | E21: =$B$8*(1+B21)*(1+C21)*(1-D21) -> 264717.3 | F21: =E21/$B$8-1 -> 0.155
A22: Pessimistic | B22: 0 | C22: -0.1 | D22: 0.05 | E22: =$B$8*(1+B22)*(1+C22)*(1-D22) -> 195959.56 | F22: =E22/$B$8-1 -> -0.145
A23: Promo push | B23: -0.05 | C23: 0.2 | D23: 0 | E23: =$B$8*(1+B23)*(1+C23)*(1-D23) -> 261279.42 | F23: =E23/$B$8-1 -> 0.14

Sheet Dashboard
A1: Sales Dashboard - Apr 2024 to Apr 2025
A3: KPI | B3: Actual | C3: Target | D3: % of Target | F3: Highlights
A4: Total Revenue | B4: =SUM(Data!$N$2:$N$251) -> 229192.47 | C4: 200000 | D4: =B4/C4 -> 1.1459624 | F4: Top customer | G4: =Customers!S6 -> Mark Carter
A5: Orders | B5: =COUNTA(Data!$A$2:$A$251) -> 250 | C5: 250 | D5: =B5/C5 -> 1 | F5: Most frequent buyer | G5: =Customers!D57 -> Mark Carter
A6: Units Sold | B6: =SUM(Data!$H$2:$H$251) -> 753 | C6: 700 | D6: =B6/C6 -> 1.0757143 | F6: Most ordered product | G6: =Analysis!E15 -> Bookshelf
A7: Avg Order Value | B7: =B4/B5 -> 916.76988 | C7: 800 | D7: =B7/C7 -> 1.1459624 | F7: Top revenue product | G7: =Analysis!E17 -> Laptop
A8: Active Customers | B8: =COUNTIF(Customers!D6:D55,">0") -> 50 | C8: 50 | D8: =B8/C8 -> 1 | F8: Top region | G8: =INDEX(Analysis!A27:A31,MATCH(MAX(Analysis!C27:C31),Analysis!C27:C31,0)) -> East
A9: High-Value Cust. Revenue Share | B9: =Customers!D59 -> 0.40955822 | C9: 0.5 | D9: =B9/C9 -> 0.81911644 | F9: Peak month | G9: =INDEX(Monthly_Trend!B5:B17,MATCH(MAX(Monthly_Trend!C6:C16),Monthly_Trend!C6:C16,0)+1) -> Jan 2025
F10: Report refreshed | G10: =NOW() -> 46325.374

Sheet Lists_Filter
A1: Compare Two Lists and Multi-value Filter
A3: List A: Electronics buyers | B3: List B: Furniture buyers | C3: Matches (in both lists) | D3: Abbrev. of match | F3: Matches found | G3: =COUNTIF(C4:C47,"?*") -> 34 | I3: FILTER-style extraction
A4: Arthur Edwards | B4: Arthur Edwards | C4: =IF(COUNTIF($B$4:$B$40,A4)>0,A4,"") -> Arthur Edwards | D4: =IF(C4="","",UPPER(LEFT(C4,1))&UPPER(MID(C4,FIND(" ",C4)+1,1))) -> AE | F4: Only in A | G4: =COUNTA(A4:A47)-G3 -> 9 | I4: Region | J4: North
A5: Barbara Young | B5: Betty Campbell | C5: =IF(COUNTIF($B$4:$B$40,A5)>0,A5,"") | D5: =IF(C5="","",UPPER(LEFT(C5,1))&UPPER(MID(C5,FIND(" ",C5)+1,1))) | F5: Only in B | G5: =COUNTA(B4:B40)-G3 -> 3 | I5: Category | J5: Electronics
A6: Betty Campbell | B6: Carol Evans | C6: =IF(COUNTIF($B$4:$B$40,A6)>0,A6,"") -> Betty Campbell | D6: =IF(C6="","",UPPER(LEFT(C6,1))&UPPER(MID(C6,FIND(" ",C6)+1,1))) -> BC | I6: Matching rows | J6: =SUMPRODUCT((Data!$K$2:$K$251=J4)*(Data!$G$2:$G$251=J5)) -> 36
A7: Carol Evans | B7: Charles Allen | C7: =IF(COUNTIF($B$4:$B$40,A7)>0,A7,"") -> Carol Evans | D7: =IF(C7="","",UPPER(LEFT(C7,1))&UPPER(MID(C7,FIND(" ",C7)+1,1))) -> CE | I7: Matching revenue | J7: =SUMIFS(Data!$N$2:$N$251,Data!$K$2:$K$251,J4,Data!$G$2:$G$251,J5) -> 39239.04
A8: Charles Allen | B8: Cynthia Price | C8: =IF(COUNTIF($B$4:$B$40,A8)>0,A8,"") -> Charles Allen | D8: =IF(C8="","",UPPER(LEFT(C8,1))&UPPER(MID(C8,FIND(" ",C8)+1,1))) -> CA
A9: Cynthia Price | B9: Daniel King | C9: =IF(COUNTIF($B$4:$B$40,A9)>0,A9,"") -> Cynthia Price | D9: =IF(C9="","",UPPER(LEFT(C9,1))&UPPER(MID(C9,FIND(" ",C9)+1,1))) -> CP
A10: Daniel King | B10: David Martinez | C10: =IF(COUNTIF($B$4:$B$40,A10)>0,A10,"") -> Daniel King | D10: =IF(C10="","",UPPER(LEFT(C10,1))&UPPER(MID(C10,FIND(" ",C10)+1,1))) -> DK | I10: # | J10: Transaction | K10: Date | L10: Customer | M10: Product | N10: Amount
A11: David Martinez | B11: Dorothy Nelson | C11: =IF(COUNTIF($B$4:$B$40,A11)>0,A11,"") -> David Martinez | D11: =IF(C11="","",UPPER(LEFT(C11,1))&UPPER(MID(C11,FIND(" ",C11)+1,1))) -> DM | I11: 1 | J11: =IF(IFERROR(MATCH(I11,Data!$T$2:$T$251,0),"")="","",INDEX(Data!$A$2:$A$251,IFERROR(MATCH(I11,Data!$T$2:$T$251,0),""))) -> TRX0230 | K11: =IF(IFERROR(MATCH(I11,Data!$T$2:$T$251,0),"")="","",INDEX(Data!$B$2:$B$251,IFERROR(MATCH(I11,Data!$T$2:$T$251,0),""))) -> 45409 | L11: =IF(IFERROR(MATCH(I11,Data!$T$2:$T$251,0),"")="","",INDEX(Data!$D$2:$D$251,IFERROR(MATCH(I11,Data!$T$2:$T$251,0),""))) -> George Adams | M11: =IF(IFERROR(MATCH(I11,Data!$T$2:$T$251,0),"")="","",INDEX(Data!$F$2:$F$251,IFERROR(MATCH(I11,Data!$T$2:$T$251,0),""))) -> Laptop | N11: =IF(IFERROR(MATCH(I11,Data!$T$2:$T$251,0),"")="","",INDEX(Data!$N$2:$N$251,IFERROR(MATCH(I11,Data!$T$2:$T$251,0),""))) -> 899.99
A12: Dorothy Nelson | B12: Edward Mitchell | C12: =IF(COUNTIF($B$4:$B$40,A12)>0,A12,"") -> Dorothy Nelson | D12: =IF(C12="","",UPPER(LEFT(C12,1))&UPPER(MID(C12,FIND(" ",C12)+1,1))) -> DN | I12: 2 | J12: =IF(IFERROR(MATCH(I12,Data!$T$2:$T$251,0),"")="","",INDEX(Data!$A$2:$A$251,IFERROR(MATCH(I12,Data!$T$2:$T$251,0),""))) -> TRX0134 | K12: =IF(IFERROR(MATCH(I12,Data!$T$2:$T$251,0),"")="","",INDEX(Data!$B$2:$B$251,IFERROR(MATCH(I12,Data!$T$2:$T$251,0),""))) -> 45410 | L12: =IF(IFERROR(MATCH(I12,Data!$T$2:$T$251,0),"")="","",INDEX(Data!$D$2:$D$251,IFERROR(MATCH(I12,Data!$T$2:$T$251,0),""))) -> Maria Garcia | M12: =IF(IFERROR(MATCH(I12,Data!$T$2:$T$251,0),"")="","",INDEX(Data!$F$2:$F$251,IFERROR(MATCH(I12,Data!$T$2:$T$251,0),""))) -> Smartphone | N12: =IF(IFERROR(MATCH(I12,Data!$T$2:$T$251,0),"")="","",INDEX(Data!$N$2:$N$251,IFERROR(MATCH(I12,Data!$T$2:$T$251,0),""))) -> 1399.98
A13: Douglas Watson | B13: Elizabeth Hall | C13: =IF(COUNTIF($B$4:$B$40,A13)>0,A13,"") | D13: =IF(C13="","",UPPER(LEFT(C13,1))&UPPER(MID(C13,FIND(" ",C13)+1,1))) | I13: 3 | J13: =IF(IFERROR(MATCH(I13,Data!$T$2:$T$251,0),"")="","",INDEX(Data!$A$2:$A$251,IFERROR(MATCH(I13,Data!$T$2:$T$251,0),""))) -> TRX0222 | K13: =IF(IFERROR(MATCH(I13,Data!$T$2:$T$251,0),"")="","",INDEX(Data!$B$2:$B$251,IFERROR(MATCH(I13,Data!$T$2:$T$251,0),""))) -> 45410 | L13: =IF(IFERROR(MATCH(I13,Data!$T$2:$T$251,0),"")="","",INDEX(Data!$D$2:$D$251,IFERROR(MATCH(I13,Data!$T$2:$T$251,0),""))) -> Virginia Sanders | M13: =IF(IFERROR(MATCH(I13,Data!$T$2:$T$251,0),"")="","",INDEX(Data!$F$2:$F$251,IFERROR(MATCH(I13,Data!$T$2:$T$251,0),""))) -> Monitor | N13: =IF(IFERROR(MATCH(I13,Data!$T$2:$T$251,0),"")="","",INDEX(Data!$N$2:$N$251,IFERROR(MATCH(I13,Data!$T$2:$T$251,0),""))) -> 749.97
A14: Edward Mitchell | B14: Emma Wilson | C14: =IF(COUNTIF($B$4:$B$40,A14)>0,A14,"") -> Edward Mitchell | D14: =IF(C14="","",UPPER(LEFT(C14,1))&UPPER(MID(C14,FIND(" ",C14)+1,1))) -> EM | I14: 4 | J14: =IF(IFERROR(MATCH(I14,Data!$T$2:$T$251,0),"")="","",INDEX(Data!$A$2:$A$251,IFERROR(MATCH(I14,Data!$T$2:$T$251,0),""))) -> TRX0204 | K14: =IF(IFERROR(MATCH(I14,Data!$T$2:$T$251,0),"")="","",INDEX(Data!$B$2:$B$251,IFERROR(MATCH(I14,Data!$T$2:$T$251,0),""))) -> 45415 | L14: =IF(IFERROR(MATCH(I14,Data!$T$2:$T$251,0),"")="","",INDEX(Data!$D$2:$D$251,IFERROR(MATCH(I14,Data!$T$2:$T$251,0),""))) -> Cynthia Price | M14: =IF(IFERROR(MATCH(I14,Data!$T$2:$T$251,0),"")="","",INDEX(Data!$F$2:$F$251,IFERROR(MATCH(I14,Data!$T$2:$T$251,0),""))) -> Monitor | N14: =IF(IFERROR(MATCH(I14,Data!$T$2:$T$251,0),"")="","",INDEX(Data!$N$2:$N$251,IFERROR(MATCH(I14,Data!$T$2:$T$251,0),""))) -> 999.96
A15: Elizabeth Hall | B15: Frank Torres | C15: =IF(COUNTIF($B$4:$B$40,A15)>0,A15,"") -> Elizabeth Hall | D15: =IF(C15="","",UPPER(LEFT(C15,1))&UPPER(MID(C15,FIND(" ",C15)+1,1))) -> EH | I15: 5 | J15: =IF(IFERROR(MATCH(I15,Data!$T$2:$T$251,0),"")="","",INDEX(Data!$A$2:$A$251,IFERROR(MATCH(I15,Data!$T$2:$T$251,0),""))) -> TRX0004 | K15: =IF(IFERROR(MATCH(I15,Data!$T$2:$T$251,0),"")="","",INDEX(Data!$B$2:$B$251,IFERROR(MATCH(I15,Data!$T$2:$T$251,0),""))) -> 45424 | L15: =IF(IFERROR(MATCH(I15,Data!$T$2:$T$251,0),"")="","",INDEX(Data!$D$2:$D$251,IFERROR(MATCH(I15,Data!$T$2:$T$251,0),""))) -> Patricia Moore | M15: =IF(IFERROR(MATCH(I15,Data!$T$2:$T$251,0),"")="","",INDEX(Data!$F$2:$F$251,IFERROR(MATCH(I15,Data!$T$2:$T$251,0),""))) -> Keyboard | N15: =IF(IFERROR(MATCH(I15,Data!$T$2:$T$251,0),"")="","",INDEX(Data!$N$2:$N$251,IFERROR(MATCH(I15,Data!$T$2:$T$251,0),""))) -> 449.95
A16: Emma Wilson | B16: Helen Roberts | C16: =IF(COUNTIF($B$4:$B$40,A16)>0,A16,"") -> Emma Wilson | D16: =IF(C16="","",UPPER(LEFT(C16,1))&UPPER(MID(C16,FIND(" ",C16)+1,1))) -> EW | I16: 6 | J16: =IF(IFERROR(MATCH(I16,Data!$T$2:$T$251,0),"")="","",INDEX(Data!$A$2:$A$251,IFERROR(MATCH(I16,Data!$T$2:$T$251,0),""))) -> TRX0117 | K16: =IF(IFERROR(MATCH(I16,Data!$T$2:$T$251,0),"")="","",INDEX(Data!$B$2:$B$251,IFERROR(MATCH(I16,Data!$T$2:$T$251,0),""))) -> 45444 | L16: =IF(IFERROR(MATCH(I16,Data!$T$2:$T$251,0),"")="","",INDEX(Data!$D$2:$D$251,IFERROR(MATCH(I16,Data!$T$2:$T$251,0),""))) -> Charles Allen | M16: =IF(IFERROR(MATCH(I16,Data!$T$2:$T$251,0),"")="","",INDEX(Data!$F$2:$F$251,IFERROR(MATCH(I16,Data!$T$2:$T$251,0),""))) -> Keyboard | N16: =IF(IFERROR(MATCH(I16,Data!$T$2:$T$251,0),"")="","",INDEX(Data!$N$2:$N$251,IFERROR(MATCH(I16,Data!$T$2:$T$251,0),""))) -> 89.99
A17: George Adams | B17: Jennifer Taylor | C17: =IF(COUNTIF($B$4:$B$40,A17)>0,A17,"") | D17: =IF(C17="","",UPPER(LEFT(C17,1))&UPPER(MID(C17,FIND(" ",C17)+1,1))) | I17: 7 | J17: =IF(IFERROR(MATCH(I17,Data!$T$2:$T$251,0),"")="","",INDEX(Data!$A$2:$A$251,IFERROR(MATCH(I17,Data!$T$2:$T$251,0),""))) -> TRX0114 | K17: =IF(IFERROR(MATCH(I17,Data!$T$2:$T$251,0),"")="","",INDEX(Data!$B$2:$B$251,IFERROR(MATCH(I17,Data!$T$2:$T$251,0),""))) -> 45481 | L17: =IF(IFERROR(MATCH(I17,Data!$T$2:$T$251,0),"")="","",INDEX(Data!$D$2:$D$251,IFERROR(MATCH(I17,Data!$T$2:$T$251,0),""))) -> Barbara Young | M17: =IF(IFERROR(MATCH(I17,Data!$T$2:$T$251,0),"")="","",INDEX(Data!$F$2:$F$251,IFERROR(MATCH(I17,Data!$T$2:$T$251,0),""))) -> Keyboard | N17: =IF(IFERROR(MATCH(I17,Data!$T$2:$T$251,0),"")="","",INDEX(Data!$N$2:$N$251,IFERROR(MATCH(I17,Data!$T$2:$T$251,0),""))) -> 449.95
